Workbook

Sheet 안내
A1: 성경 애니메이션 시리즈 제작표 (대한예수교장로회 합동측 기준)
A2: 창세기~요한계시록 66권 장면·주제 분할 · 시즌제 | 작성일 2026-10-22 | 개역개정 표기 기준
A4: 제작 변수 (노란 칸만 수정하세요)
A5: 시리즈 이름(가칭) | C5: 1분 성경 | D5: 참고 영상 분석 후 확정. 유튜브 제목안에 자동 반영
A6: 숏폼 1편 길이(초) | C6: 60 | D6: A타입 업로드본 길이. 권장 45~60초
A7: 롱폼에 넣는 A 1편 길이(초) | C7: 52 | D7: 롱폼으로 묶을 때 다음 편 예고(약 8초)를 뺀 길이
A8: 롱폼 인트로+아웃트로+연결(초) | C8: 120 | D8: 진행 캐릭터 인트로 30초 + 중간 질문 10초 + 아웃트로 60초 + 연결 20초
A9: 시즌1 시작일 (월요일) | C9: 46391 | D9: 예시 날짜입니다. 반드시 월요일로 입력하세요 (신약 월·수·금·토 계산 기준)
A10: 시즌2 시작일 (월요일) | C10: =안내!$C$9+7*(ROUNDUP(MAX(COUNTIFS(A타입_제작표!$C$2:$C$799,1,A타입_제작표!$D$2:$D$799,"구약")/7,COUNTIFS(A타입_제작표!$C$2:$C$799,1,A타입_제작표!$D$2:$D$799,"신약")/4),0)+1) -> 46580 | D10: 기본값: 시즌1이 끝난 뒤 1주 쉬고 시작. 원하는 월요일 날짜를 직접 입력해도 됩니다
A11: 시즌1 목표: 구약 편수 | C11: 182 | D11: 6개월(26주) × 매일 1편
A12: 시즌1 목표: 신약 편수 | C12: 104 | D12: 6개월(26주) × 주 4편
A14: 업로드 규칙
A15: 구약 트랙 | B15: 매일 1편 (월~일)
A16: 신약 트랙 | B16: 주 4편 (월·수·금·토)
A17: 시즌 1 (약 6개월) | B17: 구원 역사의 큰 줄기 + 누구나 아는 이야기 위주로 고른 편을 성경 순서대로 업로드
A18: 시즌 2 | B18: 시즌 1에서 다루지 않은 나머지 편을 성경 순서대로 업로드. 시즌 1 + 시즌 2 = 전체(빠짐없음, '누락점검' 시트에서 확인)
A19: 회차 번호 | B19: 트랙별로 이어서 매김 (예: 시즌1 구약 #001~#182 → 시즌2 구약 #183~). 성경 순서는 A코드로 유지
A20: 롱폼 | B20: 시즌 중에는 '롱폼_시즌별'(시즌·트랙별 7편 이상 묶음)을 올리고, 전체 완료 후 '롱폼_통합본'(성경 순서 84편)을 정주행·교회 교육용으로 사용
A22: 전체 규모 (자동 계산)
A23: 숏폼 총 편수 | C23: =COUNTA(A타입_제작표!$B$2:$B$799) -> 798 | D23: 편
A24: 시즌1 구약 / 신약 | C24: =COUNTIFS(A타입_제작표!$C$2:$C$799,1,A타입_제작표!$D$2:$D$799,"구약")&" / "&COUNTIFS(A타입_제작표!$C$2:$C$799,1,A타입_제작표!$D$2:$D$799,"신약") -> 182 / 104 | D24: 편
A25: 시즌2 구약 / 신약 | C25: =COUNTIFS(A타입_제작표!$C$2:$C$799,2,A타입_제작표!$D$2:$D$799,"구약")&" / "&COUNTIFS(A타입_제작표!$C$2:$C$799,2,A타입_제작표!$D$2:$D$799,"신약") -> 339 / 173 | D25: 편
A26: 시즌1 종료일 | C26: =_xlfn.MAXIFS(A타입_제작표!$U$2:$U$799,A타입_제작표!$C$2:$C$799,1) -> 46572
A27: 시즌2 종료일 (전체 완주) | C27: =_xlfn.MAXIFS(A타입_제작표!$U$2:$U$799,A타입_제작표!$C$2:$C$799,2) -> 46918
A28: 시즌1 기간 | C28: =ROUND((C26-안내!$C$9+1)/7,1) -> 26 | D28: 주
A29: 전체 기간 | C29: =ROUND((C27-안내!$C$9+1)/7,1) -> 75.4 | D29: 주 (쉬는 주 포함)
A30: 시즌별 롱폼 편수 | C30: =COUNTA(롱폼_시즌별!$B$2:$B$86) -> 85 | D30: 편
A31: 통합본 롱폼 편수 | C31: =COUNTA(롱폼_통합본!$B$2:$B$85) -> 84 | D31: 편
A32: 숏폼 총 분량 | C32: =ROUND(C23*안내!$C$6/3600,1) -> 13.3 | D32: 시간
A34: 분할 기준
A35: A타입 (숏폼·릴스) | B35: 45~60초, 장면 1개 · 메시지 1개. 이야기 책은 '장면형', 시가서·서신서·예언 등은 '주제형'으로 분할
A36: 롱폼 | B36: A타입 7편 이상을 하나의 이야기 단위로 묶어 약 8분 이상
A37: 진행 캐릭터 (절충안) | B37: A타입: 마지막 2~3초 등장(다음 편 안내) / 롱폼: 인트로·중간 질문·아웃트로 진행
A38: 스토리형 원칙 | B38: 쉬운 말 내레이션 + 핵심 구절 1개만 개역개정 인용. 성경에 없는 대사·장면은 최소화하고 '상상 장면'으로 감수
A39: 구속사 관점 | B39: 모든 롱폼에 '그리스도 연결점'을 두어 도덕 교훈에 그치지 않고 그리스도를 가리키도록 구성
A40: 시즌1 연결 내레이션 | B40: 시즌1은 중간 편을 건너뛰므로, A타입 '연결 내레이션' 칸에 적힌 건너뛴 내용을 1~2문장으로 요약해 흐름을 이어 줌
A41: 선별 분할한 책 | B41: 시편: 150편 중 대표 시편 31편을 5권 구조 순서로 선별; 마가복음: 마태복음과 겹치는 사건은 제외, 마가 고유 장면 위주 선별; 누가복음: 탄생 이야기와 누가 고유 비유·장면 위주 선별; 요한복음: 21장 전체를 다루되 일부 강화(講話)는 대표 단락으로 압축; 역대상: 사무엘서와 겹치는 내용은 압축, 역대기 고유 관점 중심; 역대하: 열왕기와 겹치는 내용은 압축, 역대기 고유 관점 중심
A43: 시트 구성
A44: A타입_제작표 | B44: 숏폼 전체 798편: 시즌, 트랙 회차, 본문, 제목, 첫 3초 훅, 핵심 구절, 메시지, 인물, 배경, 교리·연출 주의, 연결 내레이션, 업로드일, 제작 상태
A45: 롱폼_시즌별 | B45: 시즌 중 올릴 롱폼: 시즌·트랙별 묶음, 공개 예정일
...

Sheet A타입_제작표
A1: 순번 | B1: A코드 | C1: 시즌 | D1: 트랙 | E1: 트랙 회차 | F1: 회차 표기 | G1: 통합본 B | H1: 시즌 롱폼 | I1: 책 | J1: 본문 | K1: 유형 | L1: 제목 | M1: 첫 3초 훅 | N1: 핵심 구절 | O1: 한 줄 메시지 | P1: 등장인물 | Q1: 장소·배경 | R1: 교리·연출 주의 | S1: 연결 내레이션 | T1: 유튜브 제목안 | U1: 업로드 예정일 | V1: 요일 | W1: 다음 편 예고 | X1: 대본 | Y1: 교리감수 | Z1: 영상 | AA1: 업로드 | AB1: 비고 | AC1: 트랙키 | AD1: 시즌 내 순서
A2: 1 | B2: A0001 | C2: 1 | D2: 구약 | E2: =IF(C2=1,COUNTIFS($C$2:C2,1,$D$2:D2,D2),COUNTIFS($C$2:$C$799,1,$D$2:$D$799,D2)+COUNTIFS($C$2:C2,2,$D$2:D2,D2)) -> 1 | F2: =D2&" #"&TEXT(E2,"000") -> 구약 #001 | G2: B001 | H2: S1-L01 | I2: 창세기 | J2: 창 1:1-5 | K2: 장면 | L2: 태초에 | M2: 세상이 생기기 전엔 무엇이 있었을까? | N2: 창 1:1 | O2: 모든 것은 하나님에게서 시작되었습니다 | P2: 하나님(빛·음성) | Q2: 혼돈하고 깊은 물 위 | R2: 성부 하나님은 빛과 음성으로만 표현 | S2: 앞 편과 바로 이어짐 | T2: ="["&안내!$C$5&" "&F2&"] "&L2&" | "&J2 -> [1분 성경 구약 #001] 태초에 | 창 1:1-5 | U2: =IF(D2="구약",IF(C2=1,안내!$C$9,안내!$C$10)+AD2-1,IF(C2=1,안내!$C$9,안내!$C$10)+7*INT((AD2-1)/4)+CHOOSE(MOD(AD2-1,4)+1,0,2,4,5)) -> 46391 | V2: =CHOOSE(WEEKDAY(U2,2),"월","화","수","목","금","토","일") -> 월 | W2: =IFERROR(IF(INDEX($C$2:$C$799,MATCH(D2&"#"&(E2+1),$AC$2:$AC$799,0))=C2,"다음 편: ","시즌1 완결 · 시즌2 첫 편: ")&INDEX($L$2:$L$799,MATCH(D2&"#"&(E2+1),$AC$2:$AC$799,0)),"구약 트랙 완결") -> 다음 편: 하늘과 바다와 땅 | X2: 미착수 | Y2: 미착수 | Z2: 미착수 | AA2: 미착수 | AC2: =D2&"#"&E2 -> 구약#1 | AD2: =COUNTIFS($C$2:C2,C2,$D$2:D2,D2) -> 1
A3: 2 | B3: A0002 | C3: 1 | D3: 구약 | E3: =IF(C3=1,COUNTIFS($C$2:C3,1,$D$2:D3,D3),COUNTIFS($C$2:$C$799,1,$D$2:$D$799,D3)+COUNTIFS($C$2:C3,2,$D$2:D3,D3)) -> 2 | F3: =D3&" #"&TEXT(E3,"000") -> 구약 #002 | G3: B001 | H3: S1-L01 | I3: 창세기 | J3: 창 1:6-13 | K3: 장면 | L3: 하늘과 바다와 땅 | M3: 하나님이 바다를 한쪽으로 모으셨다? | N3: 창 1:10 | O3: 하나님은 혼돈을 질서로 바꾸십니다 | P3: 하나님(음성) | Q3: 물이 나뉘는 하늘, 처음 드러난 땅 | R3: 진화론 등 과학 논쟁 연출 지양, 창조 사실에 집중 | S3: 앞 편과 바로 이어짐 | T3: ="["&안내!$C$5&" "&F3&"] "&L3&" | "&J3 -> [1분 성경 구약 #002] 하늘과 바다와 땅 | 창 1:6-13 | U3: =IF(D3="구약",IF(C3=1,안내!$C$9,안내!$C$10)+AD3-1,IF(C3=1,안내!$C$9,안내!$C$10)+7*INT((AD3-1)/4)+CHOOSE(MOD(AD3-1,4)+1,0,2,4,5)) -> 46392 | V3: =CHOOSE(WEEKDAY(U3,2),"월","화","수","목","금","토","일") -> 화 | W3: =IFERROR(IF(INDEX($C$2:$C$799,MATCH(D3&"#"&(E3+1),$AC$2:$AC$799,0))=C3,"다음 편: ","시즌1 완결 · 시즌2 첫 편: ")&INDEX($L$2:$L$799,MATCH(D3&"#"&(E3+1),$AC$2:$AC$799,0)),"구약 트랙 완결") -> 다음 편: 해·달·별, 그리고 생명들 | X3: 미착수 | Y3: 미착수 | Z3: 미착수 | AA3: 미착수 | AC3: =D3&"#"&E3 -> 구약#2 | AD3: =COUNTIFS($C$2:C3,C3,$D$2:D3,D3) -> 2
A4: 3 | B4: A0003 | C4: 1 | D4: 구약 | E4: =IF(C4=1,COUNTIFS($C$2:C4,1,$D$2:D4,D4),COUNTIFS($C$2:$C$799,1,$D$2:$D$799,D4)+COUNTIFS($C$2:C4,2,$D$2:D4,D4)) -> 3 | F4: =D4&" #"&TEXT(E4,"000") -> 구약 #003 | G4: B001 | H4: S1-L01 | I4: 창세기 | J4: 창 1:14-25 | K4: 장면 | L4: 해·달·별, 그리고 생명들 | M4: 해보다 식물이 먼저 만들어졌다? | N4: 창 1:25 | O4: 하나님이 지으신 모든 것이 좋았습니다 | P4: 하나님(음성) | Q4: 별이 빛나는 하늘, 바다 생물, 들짐승 | S4: 앞 편과 바로 이어짐 | T4: ="["&안내!$C$5&" "&F4&"] "&L4&" | "&J4 -> [1분 성경 구약 #003] 해·달·별, 그리고 생명들 | 창 1:14-25 | U4: =IF(D4="구약",IF(C4=1,안내!$C$9,안내!$C$10)+AD4-1,IF(C4=1,안내!$C$9,안내!$C$10)+7*INT((AD4-1)/4)+CHOOSE(MOD(AD4-1,4)+1,0,2,4,5)) -> 46393 | V4: =CHOOSE(WEEKDAY(U4,2),"월","화","수","목","금","토","일") -> 수 | W4: =IFERROR(IF(INDEX($C$2:$C$799,MATCH(D4&"#"&(E4+1),$AC$2:$AC$799,0))=C4,"다음 편: ","시즌1 완결 · 시즌2 첫 편: ")&INDEX($L$2:$L$799,MATCH(D4&"#"&(E4+1),$AC$2:$AC$799,0)),"구약 트랙 완결") -> 다음 편: 하나님의 형상, 사람 | X4: 미착수 | Y4: 미착수 | Z4: 미착수 | AA4: 미착수 | AC4: =D4&"#"&E4 -> 구약#3 | AD4: =COUNTIFS($C$2:C4,C4,$D$2:D4,D4) -> 3
A5: 4 | B5: A0004 | C5: 1 | D5: 구약 | E5: =IF(C5=1,COUNTIFS($C$2:C5,1,$D$2:D5,D5),COUNTIFS($C$2:$C$799,1,$D$2:$D$799,D5)+COUNTIFS($C$2:C5,2,$D$2:D5,D5)) -> 4 | F5: =D5&" #"&TEXT(E5,"000") -> 구약 #004 | G5: B001 | H5: S1-L01 | I5: 창세기 | J5: 창 1:26-2:3 | K5: 장면 | L5: 하나님의 형상, 사람 | M5: 사람만 특별하게 만드신 이유가 있다? | N5: 창 1:27 | O5: 사람은 하나님의 형상으로 지음받은 존재입니다 | P5: 아담·하와 | Q5: 에덴 | R5: 노출 없는 자연스러운 연출(실루엣·식물로 가림) | S5: 앞 편과 바로 이어짐 | T5: ="["&안내!$C$5&" "&F5&"] "&L5&" | "&J5 -> [1분 성경 구약 #004] 하나님의 형상, 사람 | 창 1:26-2:3 | U5: =IF(D5="구약",IF(C5=1,안내!$C$9,안내!$C$10)+AD5-1,IF(C5=1,안내!$C$9,안내!$C$10)+7*INT((AD5-1)/4)+CHOOSE(MOD(AD5-1,4)+1,0,2,4,5)) -> 46394 | V5: =CHOOSE(WEEKDAY(U5,2),"월","화","수","목","금","토","일") -> 목 | W5: =IFERROR(IF(INDEX($C$2:$C$799,MATCH(D5&"#"&(E5+1),$AC$2:$AC$799,0))=C5,"다음 편: ","시즌1 완결 · 시즌2 첫 편: ")&INDEX($L$2:$L$799,MATCH(D5&"#"&(E5+1),$AC$2:$AC$799,0)),"구약 트랙 완결") -> 다음 편: 에덴동산과 한 가지 명령 | X5: 미착수 | Y5: 미착수 | Z5: 미착수 | AA5: 미착수 | AC5: =D5&"#"&E5 -> 구약#4 | AD5: =COUNTIFS($C$2:C5,C5,$D$2:D5,D5) -> 4
A6: 5 | B6: A0005 | C6: 1 | D6: 구약 | E6: =IF(C6=1,COUNTIFS($C$2:C6,1,$D$2:D6,D6),COUNTIFS($C$2:$C$799,1,$D$2:$D$799,D6)+COUNTIFS($C$2:C6,2,$D$2:D6,D6)) -> 5 | F6: =D6&" #"&TEXT(E6,"000") -> 구약 #005 | G6: B001 | H6: S1-L01 | I6: 창세기 | J6: 창 2:4-17 | K6: 장면 | L6: 에덴동산과 한 가지 명령 | M6: 딱 하나만 먹지 말라고 하신 이유는? | N6: 창 2:17 | O6: 하나님의 말씀 안에 참 자유가 있습니다 | P6: 아담 | Q6: 에덴동산, 생명나무, 선악을 알게 하는 나무 | R6: 선악과는 '사과'로 단정하지 말고 '열매'로 표현 | S6: 앞 편과 바로 이어짐 | T6: ="["&안내!$C$5&" "&F6&"] "&L6&" | "&J6 -> [1분 성경 구약 #005] 에덴동산과 한 가지 명령 | 창 2:4-17 | U6: =IF(D6="구약",IF(C6=1,안내!$C$9,안내!$C$10)+AD6-1,IF(C6=1,안내!$C$9,안내!$C$10)+7*INT((AD6-1)/4)+CHOOSE(MOD(AD6-1,4)+1,0,2,4,5)) -> 46395 | V6: =CHOOSE(WEEKDAY(U6,2),"월","화","수","목","금","토","일") -> 금 | W6: =IFERROR(IF(INDEX($C$2:$C$799,MATCH(D6&"#"&(E6+1),$AC$2:$AC$799,0))=C6,"다음 편: ","시즌1 완결 · 시즌2 첫 편: ")&INDEX($L$2:$L$799,MATCH(D6&"#"&(E6+1),$AC$2:$AC$799,0)),"구약 트랙 완결") -> 다음 편: 첫 번째 가정 | X6: 미착수 | Y6: 미착수 | Z6: 미착수 | AA6: 미착수 | AC6: =D6&"#"&E6 -> 구약#5 | AD6: =COUNTIFS($C$2:C6,C6,$D$2:D6,D6) -> 5
A7: 6 | B7: A0006 | C7: 1 | D7: 구약 | E7: =IF(C7=1,COUNTIFS($C$2:C7,1,$D$2:D7,D7),COUNTIFS($C$2:$C$799,1,$D$2:$D$799,D7)+COUNTIFS($C$2:C7,2,$D$2:D7,D7)) -> 6 | F7: =D7&" #"&TEXT(E7,"000") -> 구약 #006 | G7: B001 | H7: S1-L01 | I7: 창세기 | J7: 창 2:18-25 | K7: 장면 | L7: 첫 번째 가정 | M7: 하나님이 '좋지 않다'고 하신 단 하나는? | N7: 창 2:24 | O7: 가정은 하나님이 세우신 첫 공동체입니다 | P7: 아담·하와 | Q7: 에덴동산 | S7: 앞 편과 바로 이어짐 | T7: ="["&안내!$C$5&" "&F7&"] "&L7&" | "&J7 -> [1분 성경 구약 #006] 첫 번째 가정 | 창 2:18-25 | U7: =IF(D7="구약",IF(C7=1,안내!$C$9,안내!$C$10)+AD7-1,IF(C7=1,안내!$C$9,안내!$C$10)+7*INT((AD7-1)/4)+CHOOSE(MOD(AD7-1,4)+1,0,2,4,5)) -> 46396 | V7: =CHOOSE(WEEKDAY(U7,2),"월","화","수","목","금","토","일") -> 토 | W7: =IFERROR(IF(INDEX($C$2:$C$799,MATCH(D7&"#"&(E7+1),$AC$2:$AC$799,0))=C7,"다음 편: ","시즌1 완결 · 시즌2 첫 편: ")&INDEX($L$2:$L$799,MATCH(D7&"#"&(E7+1),$AC$2:$AC$799,0)),"구약 트랙 완결") -> 다음 편: 뱀의 유혹 | X7: 미착수 | Y7: 미착수 | Z7: 미착수 | AA7: 미착수 | AC7: =D7&"#"&E7 -> 구약#6 | AD7: =COUNTIFS($C$2:C7,C7,$D$2:D7,D7) -> 6
A8: 7 | B8: A0007 | C8: 1 | D8: 구약 | E8: =IF(C8=1,COUNTIFS($C$2:C8,1,$D$2:D8,D8),COUNTIFS($C$2:$C$799,1,$D$2:$D$799,D8)+COUNTIFS($C$2:C8,2,$D$2:D8,D8)) -> 7 | F8: =D8&" #"&TEXT(E8,"000") -> 구약 #007 | G8: B001 | H8: S1-L01 | I8: 창세기 | J8: 창 3:1-7 | K8: 장면 | L8: 뱀의 유혹 | M8: 정말 하나님이 그렇게 말씀하셨니? | N8: 창 3:6 | O8: 죄는 하나님의 말씀을 의심하는 데서 시작됩니다 | P8: 하와·아담·뱀 | Q8: 선악을 알게 하는 나무 앞 | R8: 성적 타락 해석(통일교·JMS) 절대 금지. 뱀은 뱀으로 표현 | S8: 앞 편과 바로 이어짐 | T8: ="["&안내!$C$5&" "&F8&"] "&L8&" | "&J8 -> [1분 성경 구약 #007] 뱀의 유혹 | 창 3:1-7 | U8: =IF(D8="구약",IF(C8=1,안내!$C$9,안내!$C$10)+AD8-1,IF(C8=1,안내!$C$9,안내!$C$10)+7*INT((AD8-1)/4)+CHOOSE(MOD(AD8-1,4)+1,0,2,4,5)) -> 46397 | V8: =CHOOSE(WEEKDAY(U8,2),"월","화","수","목","금","토","일") -> 일 | W8: =IFERROR(IF(INDEX($C$2:$C$799,MATCH(D8&"#"&(E8+1),$AC$2:$AC$799,0))=C8,"다음 편: ","시즌1 완결 · 시즌2 첫 편: ")&INDEX($L$2:$L$799,MATCH(D8&"#"&(E8+1),$AC$2:$AC$799,0)),"구약 트랙 완결") -> 다음 편: 네가 어디 있느냐 | X8: 미착수 | Y8: 미착수 | Z8: 미착수 | AA8: 미착수 | AC8: =D8&"#"&E8 -> 구약#7 | AD8: =COUNTIFS($C$2:C8,C8,$D$2:D8,D8) -> 7
A9: 8 | B9: A0008 | C9: 1 | D9: 구약 | E9: =IF(C9=1,COUNTIFS($C$2:C9,1,$D$2:D9,D9),COUNTIFS($C$2:$C$799,1,$D$2:$D$799,D9)+COUNTIFS($C$2:C9,2,$D$2:D9,D9)) -> 8 | F9: =D9&" #"&TEXT(E9,"000") -> 구약 #008 | G9: B001 | H9: S1-L01 | I9: 창세기 | J9: 창 3:8-13 | K9: 장면 | L9: 네가 어디 있느냐 | M9: 하나님이 정말 몰라서 물으셨을까? | N9: 창 3:9 | O9: 하나님은 숨은 죄인을 먼저 찾아오십니다 | P9: 아담·하와·하나님(음성) | Q9: 저녁 바람 부는 동산 | S9: 앞 편과 바로 이어짐 | T9: ="["&안내!$C$5&" "&F9&"] "&L9&" | "&J9 -> [1분 성경 구약 #008] 네가 어디 있느냐 | 창 3:8-13 | U9: =IF(D9="구약",IF(C9=1,안내!$C$9,안내!$C$10)+AD9-1,IF(C9=1,안내!$C$9,안내!$C$10)+7*INT((AD9-1)/4)+CHOOSE(MOD(AD9-1,4)+1,0,2,4,5)) -> 46398 | V9: =CHOOSE(WEEKDAY(U9,2),"월","화","수","목","금","토","일") -> 월 | W9: =IFERROR(IF(INDEX($C$2:$C$799,MATCH(D9&"#"&(E9+1),$AC$2:$AC$799,0))=C9,"다음 편: ","시즌1 완결 · 시즌2 첫 편: ")&INDEX($L$2:$L$799,MATCH(D9&"#"&(E9+1),$AC$2:$AC$799,0)),"구약 트랙 완결") -> 다음 편: 첫 번째 복음 | X9: 미착수 | Y9: 미착수 | Z9: 미착수 | AA9: 미착수 | AC9: =D9&"#"&E9 -> 구약#8 | AD9: =COUNTIFS($C$2:C9,C9,$D$2:D9,D9) -> 8
A10: 9 | B10: A0009 | C10: 1 | D10: 구약 | E10: =IF(C10=1,COUNTIFS($C$2:C10,1,$D$2:D10,D10),COUNTIFS($C$2:$C$799,1,$D$2:$D$799,D10)+COUNTIFS($C$2:C10,2,$D$2:D10,D10)) -> 9 | F10: =D10&" #"&TEXT(E10,"000") -> 구약 #009 | G10: B001 | H10: S1-L01 | I10: 창세기 | J10: 창 3:14-19 | K10: 장면 | L10: 첫 번째 복음 | M10: 저주의 한가운데 숨겨진 약속이 있다? | N10: 창 3:15 | O10: 하나님은 심판 중에도 구원을 약속하셨습니다 | P10: 하나님(음성)·뱀·아담·하와 | Q10: 에덴동산 | R10: 3:15 원시복음 = 그리스도의 승리로 연결 | S10: 앞 편과 바로 이어짐 | T10: ="["&안내!$C$5&" "&F10&"] "&L10&" | "&J10 -> [1분 성경 구약 #009] 첫 번째 복음 | 창 3:14-19 | U10: =IF(D10="구약",IF(C10=1,안내!$C$9,안내!$C$10)+AD10-1,IF(C10=1,안내!$C$9,안내!$C$10)+7*INT((AD10-1)/4)+CHOOSE(MOD(AD10-1,4)+1,0,2,4,5)) -> 46399 | V10: =CHOOSE(WEEKDAY(U10,2),"월","화","수","목","금","토","일") -> 화 | W10: =IFERROR(IF(INDEX($C$2:$C$799,MATCH(D10&"#"&(E10+1),$AC$2:$AC$799,0))=C10,"다음 편: ","시즌1 완결 · 시즌2 첫 편: ")&INDEX($L$2:$L$799,MATCH(D10&"#"&(E10+1),$AC$2:$AC$799,0)),"구약 트랙 완결") -> 다음 편: 가죽옷과 에덴 밖으로 | X10: 미착수 | Y10: 미착수 | Z10: 미착수 | AA10: 미착수 | AC10: =D10&"#"&E10 -> 구약#9 | AD10: =COUNTIFS($C$2:C10,C10,$D$2:D10,D10) -> 9
A11: 10 | B11: A0010 | C11: 1 | D11: 구약 | E11: =IF(C11=1,COUNTIFS($C$2:C11,1,$D$2:D11,D11),COUNTIFS($C$2:$C$799,1,$D$2:$D$799,D11)+COUNTIFS($C$2:C11,2,$D$2:D11,D11)) -> 10 | F11: =D11&" #"&TEXT(E11,"000") -> 구약 #010 | G11: B001 | H11: S1-L01 | I11: 창세기 | J11: 창 3:20-24 | K11: 장면 | L11: 가죽옷과 에덴 밖으로 | M11: 하나님이 직접 옷을 만들어 입히셨다? | N11: 창 3:21 | O11: 죄인을 덮으시는 하나님의 은혜가 시작됩니다 | P11: 아담·하와·그룹(천사) | Q11: 에덴 동쪽, 불 칼 | R11: 그룹은 날개 달린 아기천사(큐피드)로 표현 금지 | S11: 앞 편과 바로 이어짐 | T11: ="["&안내!$C$5&" "&F11&"] "&L11&" | "&J11 -> [1분 성경 구약 #010] 가죽옷과 에덴 밖으로 | 창 3:20-24 | U11: =IF(D11="구약",IF(C11=1,안내!$C$9,안내!$C$10)+AD11-1,IF(C11=1,안내!$C$9,안내!$C$10)+7*INT((AD11-1)/4)+CHOOSE(MOD(AD11-1,4)+1,0,2,4,5)) -> 46400 | V11: =CHOOSE(WEEKDAY(U11,2),"월","화","수","목","금","토","일") -> 수 | W11: =IFERROR(IF(INDEX($C$2:$C$799,MATCH(D11&"#"&(E11+1),$AC$2:$AC$799,0))=C11,"다음 편: ","시즌1 완결 · 시즌2 첫 편: ")&INDEX($L$2:$L$799,MATCH(D11&"#"&(E11+1),$AC$2:$AC$799,0)),"구약 트랙 완결") -> 다음 편: 가인과 아벨 | X11: 미착수 | Y11: 미착수 | Z11: 미착수 | AA11: 미착수 | AC11: =D11&"#"&E11 -> 구약#10 | AD11: =COUNTIFS($C$2:C11,C11,$D$2:D11,D11) -> 10
A12: 11 | B12: A0011 | C12: 1 | D12: 구약 | E12: =IF(C12=1,COUNTIFS($C$2:C12,1,$D$2:D12,D12),COUNTIFS($C$2:$C$799,1,$D$2:$D$799,D12)+COUNTIFS($C$2:C12,2,$D$2:D12,D12)) -> 11 | F12: =D12&" #"&TEXT(E12,"000") -> 구약 #011 | G12: B002 | H12: S1-L02 | I12: 창세기 | J12: 창 4:1-8 | K12: 장면 | L12: 가인과 아벨 | M12: 형제 사이에 처음으로 일어난 비극 | N12: 창 4:7 | O12: 죄는 문 앞에 엎드려 우리를 노립니다 | P12: 가인·아벨 | Q12: 들판, 제단 | R12: 살해 장면 직접 묘사 금지(암시) | S12: 앞 편과 바로 이어짐 | T12: ="["&안내!$C$5&" "&F12&"] "&L12&" | "&J12 -> [1분 성경 구약 #011] 가인과 아벨 | 창 4:1-8 | U12: =IF(D12="구약",IF(C12=1,안내!$C$9,안내!$C$10)+AD12-1,IF(C12=1,안내!$C$9,안내!$C$10)+7*INT((AD12-1)/4)+CHOOSE(MOD(AD12-1,4)+1,0,2,4,5)) -> 46401 | V12: =CHOOSE(WEEKDAY(U12,2),"월","화","수","목","금","토","일") -> 목 | W12: =IFERROR(IF(INDEX($C$2:$C$799,MATCH(D12&"#"&(E12+1),$AC$2:$AC$799,0))=C12,"다음 편: ","시즌1 완결 · 시즌2 첫 편: ")&INDEX($L$2:$L$799,MATCH(D12&"#"&(E12+1),$AC$2:$AC$799,0)),"구약 트랙 완결") -> 다음 편: 하나님과 동행한 에녹 | X12: 미착수 | Y12: 미착수 | Z12: 미착수 | AA12: 미착수 | AC12: =D12&"#"&E12 -> 구약#11 | AD12: =COUNTIFS($C$2:C12,C12,$D$2:D12,D12) -> 11
A13: 12 | B13: A0012 | C13: 2 | D13: 구약 | E13: =IF(C13=1,COUNTIFS($C$2:C13,1,$D$2:D13,D13),COUNTIFS($C$2:$C$799,1,$D$2:$D$799,D13)+COUNTIFS($C$2:C13,2,$D$2:D13,D13)) -> 183 | F13: =D13&" #"&TEXT(E13,"000") -> 구약 #183 | G13: B002 | H13: S2-L01 | I13: 창세기 | J13: 창 4:9-16 | K13: 장면 | L13: 네 아우가 어디 있느냐 | M13: 땅이 소리쳐 하나님께 호소했다? | N13: 창 4:10 | O13: 하나님은 감춘 죄도 다 아십니다 | P13: 가인·하나님(음성) | Q13: 들판, 놋 땅 | R13: 가인의 표는 상상 묘사 지양 | S13: 시즌1 구약 #011 '가인과 아벨' 다음 이야기 | T13: ="["&안내!$C$5&" "&F13&"] "&L13&" | "&J13 -> [1분 성경 구약 #183] 네 아우가 어디 있느냐 | 창 4:9-16 | U13: =IF(D13="구약",IF(C13=1,안내!$C$9,안내!$C$10)+AD13-1,IF(C13=1,안내!$C$9,안내!$C$10)+7*INT((AD13-1)/4)+CHOOSE(MOD(AD13-1,4)+1,0,2,4,5)) -> 46580 | V13: =CHOOSE(WEEKDAY(U13,2),"월","화","수","목","금","토","일") -> 월 | W13: =IFERROR(IF(INDEX($C$2:$C$799,MATCH(D13&"#"&(E13+1),$AC$2:$AC$799,0))=C13,"다음 편: ","시즌1 완결 · 시즌2 첫 편: ")&INDEX($L$2:$L$799,MATCH(D13&"#"&(E13+1),$AC$2:$AC$799,0)),"구약 트랙 완결") -> 다음 편: 가인의 후손과 셋 | X13: 미착수 | Y13: 미착수 | Z13: 미착수 | AA13: 미착수 | AC13: =D13&"#"&E13 -> 구약#183 | AD13: =COUNTIFS($C$2:C13,C13,$D$2:D13,D13) -> 1
A14: 13 | B14: A0013 | C14: 2 | D14: 구약 | E14: =IF(C14=1,COUNTIFS($C$2:C14,1,$D$2:D14,D14),COUNTIFS($C$2:$C$799,1,$D$2:$D$799,D14)+COUNTIFS($C$2:C14,2,$D$2:D14,D14)) -> 184 | F14: =D14&" #"&TEXT(E14,"000") -> 구약 #184 | G14: B002 | H14: S2-L01 | I14: 창세기 | J14: 창 4:17-26 | K14: 장면 | L14: 가인의 후손과 셋 | M14: 모든 것이 무너진 뒤 시작된 한 가지 | N14: 창 4:26 | O14: 하나님은 끊어지지 않는 소망의 줄을 이어 가십니다 | P14: 라멕·셋·에노스 | Q14: 초기 도시 | S14: 시즌1 구약 #011 '가인과 아벨' 다음 이야기 | T14: ="["&안내!$C$5&" "&F14&"] "&L14&" | "&J14 -> [1분 성경 구약 #184] 가인의 후손과 셋 | 창 4:17-26 | U14: =IF(D14="구약",IF(C14=1,안내!$C$9,안내!$C$10)+AD14-1,IF(C14=1,안내!$C$9,안내!$C$10)+7*INT((AD14-1)/4)+CHOOSE(MOD(AD14-1,4)+1,0,2,4,5)) -> 46581 | V14: =CHOOSE(WEEKDAY(U14,2),"월","화","수","목","금","토","일") -> 화 | W14: =IFERROR(IF(INDEX($C$2:$C$799,MATCH(D14&"#"&(E14+1),$AC$2:$AC$799,0))=C14,"다음 편: ","시즌1 완결 · 시즌2 첫 편: ")&INDEX($L$2:$L$799,MATCH(D14&"#"&(E14+1),$AC$2:$AC$799,0)),"구약 트랙 완결") -> 다음 편: 노아의 실수와 세 아들 | X14: 미착수 | Y14: 미착수 | Z14: 미착수 | AA14: 미착수 | AC14: =D14&"#"&E14 -> 구약#184 | AD14: =COUNTIFS($C$2:C14,C14,$D$2:D14,D14) -> 2
A15: 14 | B15: A0014 | C15: 1 | D15: 구약 | E15: =IF(C15=1,COUNTIFS($C$2:C15,1,$D$2:D15,D15),COUNTIFS($C$2:$C$799,1,$D$2:$D$799,D15)+COUNTIFS($C$2:C15,2,$D$2:D15,D15)) -> 12 | F15: =D15&" #"&TEXT(E15,"000") -> 구약 #012 | G15: B002 | H15: S1-L02 | I15: 창세기 | J15: 창 5:1-32 | K15: 장면 | L15: 하나님과 동행한 에녹 | M15: 죽지 않고 하늘로 간 사람이 있다? | N15: 창 5:24 | O15: 하나님과 동행하는 삶이 가장 복된 삶입니다 | P15: 아담·에녹·므두셀라·노아 | Q15: 족보 두루마리 연출 | R15: 에녹서(위경) 내용 사용 금지 | S15: 앞에서 건너뛴 2편(시즌2): 창 4:9-16 네 아우가 어디 있느냐, 창 4:17-26 가인의 후손과 셋 → 연결 내레이션 1~2문장 필요 | T15: ="["&안내!$C$5&" "&F15&"] "&L15&" | "&J15 -> [1분 성경 구약 #012] 하나님과 동행한 에녹 | 창 5:1-32 | U15: =IF(D15="구약",IF(C15=1,안내!$C$9,안내!$C$10)+AD15-1,IF(C15=1,안내!$C$9,안내!$C$10)+7*INT((AD15-1)/4)+CHOOSE(MOD(AD15-1,4)+1,0,2,4,5)) -> 46402 | V15: =CHOOSE(WEEKDAY(U15,2),"월","화","수","목","금","토","일") -> 금 | W15: =IFERROR(IF(INDEX($C$2:$C$799,MATCH(D15&"#"&(E15+1),$AC$2:$AC$799,0))=C15,"다음 편: ","시즌1 완결 · 시즌2 첫 편: ")&INDEX($L$2:$L$799,MATCH(D15&"#"&(E15+1),$AC$2:$AC$799,0)),"구약 트랙 완결") -> 다음 편: 은혜를 입은 노아 | X15: 미착수 | Y15: 미착수 | Z15: 미착수 | AA15: 미착수 | AC15: =D15&"#"&E15 -> 구약#12 | AD15: =COUNTIFS($C$2:C15,C15,$D$2:D15,D15) -> 12
A16: 15 | B16: A0015 | C16: 1 | D16: 구약 | E16: =IF(C16=1,COUNTIFS($C$2:C16,1,$D$2:D16,D16),COUNTIFS($C$2:$C$799,1,$D$2:$D$799,D16)+COUNTIFS($C$2:C16,2,$D$2:D16,D16)) -> 13 | F16: =D16&" #"&TEXT(E16,"000") -> 구약 #013 | G16: B002 | H16: S1-L02 | I16: 창세기 | J16: 창 6:1-8 | K16: 장면 | L16: 은혜를 입은 노아 | M16: 하나님이 사람 지으신 것을 한탄하셨다? | N16: 창 6:8 | O16: 타락한 세상에서도 은혜는 있습니다 | P16: 노아 | Q16: 타락한 세상 | R16: 6:2 '하나님의 아들들' 거인·외계인 해석 연출 금지. '한탄'은 인간적 표현임을 설명 | S16: 앞 편과 바로 이어짐 | T16: ="["&안내!$C$5&" "&F16&"] "&L16&" | "&J16 -> [1분 성경 구약 #013] 은혜를 입은 노아 | 창 6:1-8 | U16: =IF(D16="구약",IF(C16=1,안내!$C$9,안내!$C$10)+AD16-1,IF(C16=1,안내!$C$9,안내!$C$10)+7*INT((AD16-1)/4)+CHOOSE(MOD(AD16-1,4)+1,0,2,4,5)) -> 46403 | V16: =CHOOSE(WEEKDAY(U16,2),"월","화","수","목","금","토","일") -> 토 | W16: =IFERROR(IF(INDEX($C$2:$C$799,MATCH(D16&"#"&(E16+1),$AC$2:$AC$799,0))=C16,"다음 편: ","시즌1 완결 · 시즌2 첫 편: ")&INDEX($L$2:$L$799,MATCH(D16&"#"&(E16+1),$AC$2:$AC$799,0)),"구약 트랙 완결") -> 다음 편: 방주를 지어라 | X16: 미착수 | Y16: 미착수 | Z16: 미착수 | AA16: 미착수 | AC16: =D16&"#"&E16 -> 구약#13 | AD16: =COUNTIFS($C$2:C16,C16,$D$2:D16,D16) -> 13
A17: 16 | B17: A0016 | C17: 1 | D17: 구약 | E17: =IF(C17=1,COUNTIFS($C$2:C17,1,$D$2:D17,D17),COUNTIFS($C$2:$C$799,1,$D$2:$D$799,D17)+COUNTIFS($C$2:C17,2,$D$2:D17,D17)) -> 14 | F17: =D17&" #"&TEXT(E17,"000") -> 구약 #014 | G17: B002 | H17: S1-L02 | I17: 창세기 | J17: 창 6:9-22 | K17: 장면 | L17: 방주를 지어라 | M17: 비 한 번 안 온 땅에서 배를 만들라고? | N17: 창 6:22 | O17: 믿음은 보이지 않는 것을 순종하는 것입니다 | P17: 노아·셈·함·야벳 | Q17: 방주 건축 현장 | S17: 앞 편과 바로 이어짐 | T17: ="["&안내!$C$5&" "&F17&"] "&L17&" | "&J17 -> [1분 성경 구약 #014] 방주를 지어라 | 창 6:9-22 | U17: =IF(D17="구약",IF(C17=1,안내!$C$9,안내!$C$10)+AD17-1,IF(C17=1,안내!$C$9,안내!$C$10)+7*INT((AD17-1)/4)+CHOOSE(MOD(AD17-1,4)+1,0,2,4,5)) -> 46404 | V17: =CHOOSE(WEEKDAY(U17,2),"월","화","수","목","금","토","일") -> 일 | W17: =IFERROR(IF(INDEX($C$2:$C$799,MATCH(D17&"#"&(E17+1),$AC$2:$AC$799,0))=C17,"다음 편: ","시즌1 완결 · 시즌2 첫 편: ")&INDEX($L$2:$L$799,MATCH(D17&"#"&(E17+1),$AC$2:$AC$799,0)),"구약 트랙 완결") -> 다음 편: 홍수 | X17: 미착수 | Y17: 미착수 | Z17: 미착수 | AA17: 미착수 | AC17: =D17&"#"&E17 -> 구약#14 | AD17: =COUNTIFS($C$2:C17,C17,$D$2:D17,D17) -> 14
A18: 17 | B18: A0017 | C18: 1 | D18: 구약 | E18: =IF(C18=1,COUNTIFS($C$2:C18,1,$D$2:D18,D18),COUNTIFS($C$2:$C$799,1,$D$2:$D$799,D18)+COUNTIFS($C$2:C18,2,$D$2:D18,D18)) -> 15 | F18: =D18&" #"&TEXT(E18,"000") -> 구약 #015 | G18: B002 | H18: S1-L02 | I18: 창세기 | J18: 창 7:1-24 | K18: 장면 | L18: 홍수 | M18: 40일 동안 그친 적 없는 비 | N18: 창 7:23 | O18: 하나님의 심판은 실제로 일어납니다 | P18: 노아 가족·동물들 | Q18: 방주 안과 밖 | R18: 익사 장면 직접 묘사 금지 | S18: 앞 편과 바로 이어짐 | T18: ="["&안내!$C$5&" "&F18&"] "&L18&" | "&J18 -> [1분 성경 구약 #015] 홍수 | 창 7:1-24 | U18: =IF(D18="구약",IF(C18=1,안내!$C$9,안내!$C$10)+AD18-1,IF(C18=1,안내!$C$9,안내!$C$10)+7*INT((AD18-1)/4)+CHOOSE(MOD(AD18-1,4)+1,0,2,4,5)) -> 46405 | V18: =CHOOSE(WEEKDAY(U18,2),"월","화","수","목","금","토","일") -> 월 | W18: =IFERROR(IF(INDEX($C$2:$C$799,MATCH(D18&"#"&(E18+1),$AC$2:$AC$799,0))=C18,"다음 편: ","시즌1 완결 · 시즌2 첫 편: ")&INDEX($L$2:$L$799,MATCH(D18&"#"&(E18+1),$AC$2:$AC$799,0)),"구약 트랙 완결") -> 다음 편: 비둘기와 감람나무 잎 | X18: 미착수 | Y18: 미착수 | Z18: 미착수 | AA18: 미착수 | AC18: =D18&"#"&E18 -> 구약#15 | AD18: =COUNTIFS($C$2:C18,C18,$D$2:D18,D18) -> 15
A19: 18 | B19: A0018 | C19: 1 | D19: 구약 | E19: =IF(C19=1,COUNTIFS($C$2:C19,1,$D$2:D19,D19),COUNTIFS($C$2:$C$799,1,$D$2:$D$799,D19)+COUNTIFS($C$2:C19,2,$D$2:D19,D19)) -> 16 | F19: =D19&" #"&TEXT(E19,"000") -> 구약 #016 | G19: B002 | H19: S1-L02 | I19: 창세기 | J19: 창 8:1-19 | K19: 장면 | L19: 비둘기와 감람나무 잎 | M19: 비둘기가 물고 온 작은 잎사귀 하나 | N19: 창 8:11 | O19: 하나님은 노아를 기억하셨습니다 | P19: 노아·까마귀·비둘기 | Q19: 아라랏 산, 물이 빠지는 땅 | S19: 앞 편과 바로 이어짐 | T19: ="["&안내!$C$5&" "&F19&"] "&L19&" | "&J19 -> [1분 성경 구약 #016] 비둘기와 감람나무 잎 | 창 8:1-19 | U19: =IF(D19="구약",IF(C19=1,안내!$C$9,안내!$C$10)+AD19-1,IF(C19=1,안내!$C$9,안내!$C$10)+7*INT((AD19-1)/4)+CHOOSE(MOD(AD19-1,4)+1,0,2,4,5)) -> 46406 | V19: =CHOOSE(WEEKDAY(U19,2),"월","화","수","목","금","토","일") -> 화 | W19: =IFERROR(IF(INDEX($C$2:$C$799,MATCH(D19&"#"&(E19+1),$AC$2:$AC$799,0))=C19,"다음 편: ","시즌1 완결 · 시즌2 첫 편: ")&INDEX($L$2:$L$799,MATCH(D19&"#"&(E19+1),$AC$2:$AC$799,0)),"구약 트랙 완결") -> 다음 편: 무지개 언약 | X19: 미착수 | Y19: 미착수 | Z19: 미착수 | AA19: 미착수 | AC19: =D19&"#"&E19 -> 구약#16 | AD19: =COUNTIFS($C$2:C19,C19,$D$2:D19,D19) -> 16
A20: 19 | B20: A0019 | C20: 1 | D20: 구약 | E20: =IF(C20=1,COUNTIFS($C$2:C20,1,$D$2:D20,D20),COUNTIFS($C$2:$C$799,1,$D$2:$D$799,D20)+COUNTIFS($C$2:C20,2,$D$2:D20,D20)) -> 17 | F20: =D20&" #"&TEXT(E20,"000") -> 구약 #017 | G20: B002 | H20: S1-L02 | I20: 창세기 | J20: 창 8:20-9:17 | K20: 장면 | L20: 무지개 언약 | M20: 무지개가 하나님의 약속이었다? | N20: 창 9:13 | O20: 하나님은 약속을 반드시 지키십니다 | P20: 노아 가족·하나님(음성) | Q20: 제단, 무지개 | R20: 무지개를 특정 단체 상징과 연결하지 말 것 | S20: 앞 편과 바로 이어짐 | T20: ="["&안내!$C$5&" "&F20&"] "&L20&" | "&J20 -> [1분 성경 구약 #017] 무지개 언약 | 창 8:20-9:17 | U20: =IF(D20="구약",IF(C20=1,안내!$C$9,안내!$C$10)+AD20-1,IF(C20=1,안내!$C$9,안내!$C$10)+7*INT((AD20-1)/4)+CHOOSE(MOD(AD20-1,4)+1,0,2,4,5)) -> 46407 | V20: =CHOOSE(WEEKDAY(U20,2),"월","화","수","목","금","토","일") -> 수 | W20: =IFERROR(IF(INDEX($C$2:$C$799,MATCH(D20&"#"&(E20+1),$AC$2:$AC$799,0))=C20,"다음 편: ","시즌1 완결 · 시즌2 첫 편: ")&INDEX($L$2:$L$799,MATCH(D20&"#"&(E20+1),$AC$2:$AC$799,0)),"구약 트랙 완결") -> 다음 편: 바벨탑 | X20: 미착수 | Y20: 미착수 | Z20: 미착수 | AA20: 미착수 | AC20: =D20&"#"&E20 -> 구약#17 | AD20: =COUNTIFS($C$2:C20,C20,$D$2:D20,D20) -> 17
A21: 20 | B21: A0020 | C21: 2 | D21: 구약 | E21: =IF(C21=1,COUNTIFS($C$2:C21,1,$D$2:D21,D21),COUNTIFS($C$2:$C$799,1,$D$2:$D$799,D21)+COUNTIFS($C$2:C21,2,$D$2:D21,D21)) -> 185 | F21: =D21&" #"&TEXT(E21,"000") -> 구약 #185 | G21: B002 | H21: S2-L01 | I21: 창세기 | J21: 창 9:18-29 | K21: 장면 | L21: 노아의 실수와 세 아들 | M21: 구원받은 의인도 넘어질 수 있다? | N21: 창 9:26 | O21: 의인도 은혜가 필요한 죄인입니다 | P21: 노아·셈·함·야벳 | Q21: 포도원, 장막 | R21: 노아 벗은 장면 직접 묘사 금지 | S21: 시즌1 구약 #017 '무지개 언약' 다음 이야기 | T21: ="["&안내!$C$5&" "&F21&"] "&L21&" | "&J21 -> [1분 성경 구약 #185] 노아의 실수와 세 아들 | 창 9:18-29 | U21: =IF(D21="구약",IF(C21=1,안내!$C$9,안내!$C$10)+AD21-1,IF(C21=1,안내!$C$9,안내!$C$10)+7*INT((AD21-1)/4)+CHOOSE(MOD(AD21-1,4)+1,0,2,4,5)) -> 46582 | V21: =CHOOSE(WEEKDAY(U21,2),"월","화","수","목","금","토","일") -> 수 | W21: =IFERROR(IF(INDEX($C$2:$C$799,MATCH(D21&"#"&(E21+1),$AC$2:$AC$799,0))=C21,"다음 편: ","시즌1 완결 · 시즌2 첫 편: ")&INDEX($L$2:$L$799,MATCH(D21&"#"&(E21+1),$AC$2:$AC$799,0)),"구약 트랙 완결") -> 다음 편: 민족들의 시작 | X21: 미착수 | Y21: 미착수 | Z21: 미착수 | AA21: 미착수 | AC21: =D21&"#"&E21 -> 구약#185 | AD21: =COUNTIFS($C$2:C21,C21,$D$2:D21,D21) -> 3
A22: 21 | B22: A0021 | C22: 2 | D22: 구약 | E22: =IF(C22=1,COUNTIFS($C$2:C22,1,$D$2:D22,D22),COUNTIFS($C$2:$C$799,1,$D$2:$D$799,D22)+COUNTIFS($C$2:C22,2,$D$2:D22,D22)) -> 186 | F22: =D22&" #"&TEXT(E22,"000") -> 구약 #186 | G22: B002 | H22: S2-L01 | I22: 창세기 | J22: 창 10:1-32 | K22: 장면 | L22: 민족들의 시작 | M22: 모든 나라가 한 가족에서 나왔다? | N22: 창 10:32 | O22: 모든 민족은 한 하나님 아래 있습니다 | P22: 노아의 후손들 | Q22: 세계 지도 연출 | S22: 시즌1 구약 #017 '무지개 언약' 다음 이야기 | T22: ="["&안내!$C$5&" "&F22&"] "&L22&" | "&J22 -> [1분 성경 구약 #186] 민족들의 시작 | 창 10:1-32 | U22: =IF(D22="구약",IF(C22=1,안내!$C$9,안내!$C$10)+AD22-1,IF(C22=1,안내!$C$9,안내!$C$10)+7*INT((AD22-1)/4)+CHOOSE(MOD(AD22-1,4)+1,0,2,4,5)) -> 46583 | V22: =CHOOSE(WEEKDAY(U22,2),"월","화","수","목","금","토","일") -> 목 | W22: =IFERROR(IF(INDEX($C$2:$C$799,MATCH(D22&"#"&(E22+1),$AC$2:$AC$799,0))=C22,"다음 편: ","시즌1 완결 · 시즌2 첫 편: ")&INDEX($L$2:$L$799,MATCH(D22&"#"&(E22+1),$AC$2:$AC$799,0)),"구약 트랙 완결") -> 다음 편: 셈에서 아브람까지 | X22: 미착수 | Y22: 미착수 | Z22: 미착수 | AA22: 미착수 | AC22: =D22&"#"&E22 -> 구약#186 | AD22: =COUNTIFS($C$2:C22,C22,$D$2:D22,D22) -> 4
A23: 22 | B23: A0022 | C23: 1 | D23: 구약 | E23: =IF(C23=1,COUNTIFS($C$2:C23,1,$D$2:D23,D23),COUNTIFS($C$2:$C$799,1,$D$2:$D$799,D23)+COUNTIFS($C$2:C23,2,$D$2:D23,D23)) -> 18 | F23: =D23&" #"&TEXT(E23,"000") -> 구약 #018 | G23: B002 | H23: S1-L02 | I23: 창세기 | J23: 창 11:1-9 | K23: 장면 | L23: 바벨탑 | M23: 하늘까지 닿으려던 사람들 | N23: 창 11:9 | O23: 하나님 없이 쌓는 이름은 무너집니다 | P23: 바벨 사람들 | Q23: 시날 평지, 벽돌 탑 | S23: 앞에서 건너뛴 2편(시즌2): 창 9:18-29 노아의 실수와 세 아들, 창 10:1-32 민족들의 시작 → 연결 내레이션 1~2문장 필요 | T23: ="["&안내!$C$5&" "&F23&"] "&L23&" | "&J23 -> [1분 성경 구약 #018] 바벨탑 | 창 11:1-9 | U23: =IF(D23="구약",IF(C23=1,안내!$C$9,안내!$C$10)+AD23-1,IF(C23=1,안내!$C$9,안내!$C$10)+7*INT((AD23-1)/4)+CHOOSE(MOD(AD23-1,4)+1,0,2,4,5)) -> 46408 | V23: =CHOOSE(WEEKDAY(U23,2),"월","화","수","목","금","토","일") -> 목 | W23: =IFERROR(IF(INDEX($C$2:$C$799,MATCH(D23&"#"&(E23+1),$AC$2:$AC$799,0))=C23,"다음 편: ","시즌1 완결 · 시즌2 첫 편: ")&INDEX($L$2:$L$799,MATCH(D23&"#"&(E23+1),$AC$2:$AC$799,0)),"구약 트랙 완결") -> 다음 편: 떠나라 | X23: 미착수 | Y23: 미착수 | Z23: 미착수 | AA23: 미착수 | AC23: =D23&"#"&E23 -> 구약#18 | AD23: =COUNTIFS($C$2:C23,C23,$D$2:D23,D23) -> 18
A24: 23 | B24: A0023 | C24: 2 | D24: 구약 | E24: =IF(C24=1,COUNTIFS($C$2:C24,1,$D$2:D24,D24),COUNTIFS($C$2:$C$799,1,$D$2:$D$799,D24)+COUNTIFS($C$2:C24,2,$D$2:D24,D24)) -> 187 | F24: =D24&" #"&TEXT(E24,"000") -> 구약 #187 | G24: B002 | H24: S2-L01 | I24: 창세기 | J24: 창 11:10-32 | K24: 장면 | L24: 셈에서 아브람까지 | M24: 하나님이 한 사람을 선택하신 이유는? | N24: 창 11:31 | O24: 하나님은 한 가정을 통해 세상을 구원하실 계획을 세우셨습니다 | P24: 셈·데라·아브람·사래·롯 | Q24: 갈대아 우르, 하란 | S24: 시즌1 구약 #018 '바벨탑' 다음 이야기 | T24: ="["&안내!$C$5&" "&F24&"] "&L24&" | "&J24 -> [1분 성경 구약 #187] 셈에서 아브람까지 | 창 11:10-32 | U24: =IF(D24="구약",IF(C24=1,안내!$C$9,안내!$C$10)+AD24-1,IF(C24=1,안내!$C$9,안내!$C$10)+7*INT((AD24-1)/4)+CHOOSE(MOD(AD24-1,4)+1,0,2,4,5)) -> 46584 | V24: =CHOOSE(WEEKDAY(U24,2),"월","화","수","목","금","토","일") -> 금 | W24: =IFERROR(IF(INDEX($C$2:$C$799,MATCH(D24&"#"&(E24+1),$AC$2:$AC$799,0))=C24,"다음 편: ","시즌1 완결 · 시즌2 첫 편: ")&INDEX($L$2:$L$799,MATCH(D24&"#"&(E24+1),$AC$2:$AC$799,0)),"구약 트랙 완결") -> 다음 편: 애굽에서의 거짓말 | X24: 미착수 | Y24: 미착수 | Z24: 미착수 | AA24: 미착수 | AC24: =D24&"#"&E24 -> 구약#187 | AD24: =COUNTIFS($C$2:C24,C24,$D$2:D24,D24) -> 5
A25: 24 | B25: A0024 | C25: 1 | D25: 구약 | E25: =IF(C25=1,COUNTIFS($C$2:C25,1,$D$2:D25,D25),COUNTIFS($C$2:$C$799,1,$D$2:$D$799,D25)+COUNTIFS($C$2:C25,2,$D$2:D25,D25)) -> 19 | F25: =D25&" #"&TEXT(E25,"000") -> 구약 #019 | G25: B003 | H25: S1-L03 | I25: 창세기 | J25: 창 12:1-9 | K25: 장면 | L25: 떠나라 | M25: 75세에 모든 것을 두고 떠나라고? | N25: 창 12:2 | O25: 믿음은 하나님의 약속을 붙잡고 떠나는 것입니다 | P25: 아브람·사래·롯 | Q25: 하란에서 가나안 세겜 | S25: 앞에서 건너뛴 1편(시즌2): 창 11:10-32 셈에서 아브람까지 → 연결 내레이션 1~2문장 필요 | T25: ="["&안내!$C$5&" "&F25&"] "&L25&" | "&J25 -> [1분 성경 구약 #019] 떠나라 | 창 12:1-9 | U25: =IF(D25="구약",IF(C25=1,안내!$C$9,안내!$C$10)+AD25-1,IF(C25=1,안내!$C$9,안내!$C$10)+7*INT((AD25-1)/4)+CHOOSE(MOD(AD25-1,4)+1,0,2,4,5)) -> 46409 | V25: =CHOOSE(WEEKDAY(U25,2),"월","화","수","목","금","토","일") -> 금 | W25: =IFERROR(IF(INDEX($C$2:$C$799,MATCH(D25&"#"&(E25+1),$AC$2:$AC$799,0))=C25,"다음 편: ","시즌1 완결 · 시즌2 첫 편: ")&INDEX($L$2:$L$799,MATCH(D25&"#"&(E25+1),$AC$2:$AC$799,0)),"구약 트랙 완결") -> 다음 편: 하늘의 별을 세어 보라 | X25: 미착수 | Y25: 미착수 | Z25: 미착수 | AA25: 미착수 | AC25: =D25&"#"&E25 -> 구약#19 | AD25: =COUNTIFS($C$2:C25,C25,$D$2:D25,D25) -> 19
A26: 25 | B26: A0025 | C26: 2 | D26: 구약 | E26: =IF(C26=1,COUNTIFS($C$2:C26,1,$D$2:D26,D26),COUNTIFS($C$2:$C$799,1,$D$2:$D$799,D26)+COUNTIFS($C$2:C26,2,$D$2:D26,D26)) -> 188 | F26: =D26&" #"&TEXT(E26,"000") -> 구약 #188 | G26: B003 | H26: S2-L01 | I26: 창세기 | J26: 창 12:10-20 | K26: 장면 | L26: 애굽에서의 거짓말 | M26: 아내를 누이라고 소개한 믿음의 조상? | N26: 창 12:17 | O26: 하나님은 우리의 실수 속에서도 약속을 지키십니다 | P26: 아브람·사래·바로 | Q26: 애굽 궁전 | S26: 시즌1 구약 #019 '떠나라' 다음 이야기 | T26: ="["&안내!$C$5&" "&F26&"] "&L26&" | "&J26 -> [1분 성경 구약 #188] 애굽에서의 거짓말 | 창 12:10-20 | U26: =IF(D26="구약",IF(C26=1,안내!$C$9,안내!$C$10)+AD26-1,IF(C26=1,안내!$C$9,안내!$C$10)+7*INT((AD26-1)/4)+CHOOSE(MOD(AD26-1,4)+1,0,2,4,5)) -> 46585 | V26: =CHOOSE(WEEKDAY(U26,2),"월","화","수","목","금","토","일") -> 토 | W26: =IFERROR(IF(INDEX($C$2:$C$799,MATCH(D26&"#"&(E26+1),$AC$2:$AC$799,0))=C26,"다음 편: ","시즌1 완결 · 시즌2 첫 편: ")&INDEX($L$2:$L$799,MATCH(D26&"#"&(E26+1),$AC$2:$AC$799,0)),"구약 트랙 완결") -> 다음 편: 롯과 갈라서다 | X26: 미착수 | Y26: 미착수 | Z26: 미착수 | AA26: 미착수 | AC26: =D26&"#"&E26 -> 구약#188 | AD26: =COUNTIFS($C$2:C26,C26,$D$2:D26,D26) -> 6
A27: 26 | B27: A0026 | C27: 2 | D27: 구약 | E27: =IF(C27=1,COUNTIFS($C$2:C27,1,$D$2:D27,D27),COUNTIFS($C$2:$C$799,1,$D$2:$D$799,D27)+COUNTIFS($C$2:C27,2,$D$2:D27,D27)) -> 189 | F27: =D27&" #"&TEXT(E27,"000") -> 구약 #189 | G27: B003 | H27: S2-L01 | I27: 창세기 | J27: 창 13:1-18 | K27: 장면 | L27: 롯과 갈라서다 | M27: 좋은 땅을 양보하면 손해일까? | N27: 창 13:9 | O27: 하나님께 맡긴 사람은 양보할 수 있습니다 | P27: 아브람·롯 | Q27: 벧엘, 요단 들판 | S27: 시즌1 구약 #019 '떠나라' 다음 이야기 | T27: ="["&안내!$C$5&" "&F27&"] "&L27&" | "&J27 -> [1분 성경 구약 #189] 롯과 갈라서다 | 창 13:1-18 | U27: =IF(D27="구약",IF(C27=1,안내!$C$9,안내!$C$10)+AD27-1,IF(C27=1,안내!$C$9,안내!$C$10)+7*INT((AD27-1)/4)+CHOOSE(MOD(AD27-1,4)+1,0,2,4,5)) -> 46586 | V27: =CHOOSE(WEEKDAY(U27,2),"월","화","수","목","금","토","일") -> 일 | W27: =IFERROR(IF(INDEX($C$2:$C$799,MATCH(D27&"#"&(E27+1),$AC$2:$AC$799,0))=C27,"다음 편: ","시즌1 완결 · 시즌2 첫 편: ")&INDEX($L$2:$L$799,MATCH(D27&"#"&(E27+1),$AC$2:$AC$799,0)),"구약 트랙 완결") -> 다음 편: 롯을 구하고 멜기세덱을 만나다 | X27: 미착수 | Y27: 미착수 | Z27: 미착수 | AA27: 미착수 | AC27: =D27&"#"&E27 -> 구약#189 | AD27: =COUNTIFS($C$2:C27,C27,$D$2:D27,D27) -> 7
A28: 27 | B28: A0027 | C28: 2 | D28: 구약 | E28: =IF(C28=1,COUNTIFS($C$2:C28,1,$D$2:D28,D28),COUNTIFS($C$2:$C$799,1,$D$2:$D$799,D28)+COUNTIFS($C$2:C28,2,$D$2:D28,D28)) -> 190 | F28: =D28&" #"&TEXT(E28,"000") -> 구약 #190 | G28: B003 | H28: S2-L01 | I28: 창세기 | J28: 창 14:1-24 | K28: 장면 | L28: 롯을 구하고 멜기세덱을 만나다 | M28: 318명으로 왕들의 연합군을 이겼다? | N28: 창 14:20 | O28: 모든 승리는 하나님께로부터 옵니다 | P28: 아브람·롯·멜기세덱 | Q28: 단까지의 추격, 살렘 | R28: 멜기세덱 = 그리스도의 예표(히 7)로만 설명, 특정인 대입 금지 | S28: 시즌1 구약 #019 '떠나라' 다음 이야기 | T28: ="["&안내!$C$5&" "&F28&"] "&L28&" | "&J28 -> [1분 성경 구약 #190] 롯을 구하고 멜기세덱을 만나다 | 창 14:1-24 | U28: =IF(D28="구약",IF(C28=1,안내!$C$9,안내!$C$10)+AD28-1,IF(C28=1,안내!$C$9,안내!$C$10)+7*INT((AD28-1)/4)+CHOOSE(MOD(AD28-1,4)+1,0,2,4,5)) -> 46587 | V28: =CHOOSE(WEEKDAY(U28,2),"월","화","수","목","금","토","일") -> 월 | W28: =IFERROR(IF(INDEX($C$2:$C$799,MATCH(D28&"#"&(E28+1),$AC$2:$AC$799,0))=C28,"다음 편: ","시즌1 완결 · 시즌2 첫 편: ")&INDEX($L$2:$L$799,MATCH(D28&"#"&(E28+1),$AC$2:$AC$799,0)),"구약 트랙 완결") -> 다음 편: 하갈과 이스마엘 | X28: 미착수 | Y28: 미착수 | Z28: 미착수 | AA28: 미착수 | AC28: =D28&"#"&E28 -> 구약#190 | AD28: =COUNTIFS($C$2:C28,C28,$D$2:D28,D28) -> 8
A29: 28 | B29: A0028 | C29: 1 | D29: 구약 | E29: =IF(C29=1,COUNTIFS($C$2:C29,1,$D$2:D29,D29),COUNTIFS($C$2:$C$799,1,$D$2:$D$799,D29)+COUNTIFS($C$2:C29,2,$D$2:D29,D29)) -> 20 | F29: =D29&" #"&TEXT(E29,"000") -> 구약 #020 | G29: B003 | H29: S1-L03 | I29: 창세기 | J29: 창 15:1-21 | K29: 장면 | L29: 하늘의 별을 세어 보라 | M29: 밤하늘의 별을 세라고 하신 이유 | N29: 창 15:6 | O29: 하나님은 믿음을 의로 여기십니다 | P29: 아브람·하나님(음성) | Q29: 별이 가득한 밤하늘, 쪼갠 제물 사이 횃불 | R29: 이신칭의 핵심 구절 | S29: 앞에서 건너뛴 3편(시즌2): 창 12:10-20 애굽에서의 거짓말, 창 13:1-18 롯과 갈라서다, 창 14:1-24 롯을 구하고 멜기세덱을 만나다 → 연결 내레이션 1~2문장 필요 | T29: ="["&안내!$C$5&" "&F29&"] "&L29&" | "&J29 -> [1분 성경 구약 #020] 하늘의 별을 세어 보라 | 창 15:1-21 | U29: =IF(D29="구약",IF(C29=1,안내!$C$9,안내!$C$10)+AD29-1,IF(C29=1,안내!$C$9,안내!$C$10)+7*INT((AD29-1)/4)+CHOOSE(MOD(AD29-1,4)+1,0,2,4,5)) -> 46410 | V29: =CHOOSE(WEEKDAY(U29,2),"월","화","수","목","금","토","일") -> 토 | W29: =IFERROR(IF(INDEX($C$2:$C$799,MATCH(D29&"#"&(E29+1),$AC$2:$AC$799,0))=C29,"다음 편: ","시즌1 완결 · 시즌2 첫 편: ")&INDEX($L$2:$L$799,MATCH(D29&"#"&(E29+1),$AC$2:$AC$799,0)),"구약 트랙 완결") -> 다음 편: 세 나그네 | X29: 미착수 | Y29: 미착수 | Z29: 미착수 | AA29: 미착수 | AC29: =D29&"#"&E29 -> 구약#20 | AD29: =COUNTIFS($C$2:C29,C29,$D$2:D29,D29) -> 20
A30: 29 | B30: A0029 | C30: 2 | D30: 구약 | E30: =IF(C30=1,COUNTIFS($C$2:C30,1,$D$2:D30,D30),COUNTIFS($C$2:$C$799,1,$D$2:$D$799,D30)+COUNTIFS($C$2:C30,2,$D$2:D30,D30)) -> 191 | F30: =D30&" #"&TEXT(E30,"000") -> 구약 #191 | G30: B003 | H30: S2-L01 | I30: 창세기 | J30: 창 16:1-16 | K30: 장면 | L30: 하갈과 이스마엘 | M30: 기다리다 지쳐 선택한 지름길 | N30: 창 16:13 | O30: 하나님은 버려진 사람도 보고 계십니다 | P30: 사래·하갈·아브람·여호와의 사자 | Q30: 광야의 샘 | R30: 여호와의 사자는 빛나는 형체로 | S30: 시즌1 구약 #020 '하늘의 별을 세어 보라' 다음 이야기 | T30: ="["&안내!$C$5&" "&F30&"] "&L30&" | "&J30 -> [1분 성경 구약 #191] 하갈과 이스마엘 | 창 16:1-16 | U30: =IF(D30="구약",IF(C30=1,안내!$C$9,안내!$C$10)+AD30-1,IF(C30=1,안내!$C$9,안내!$C$10)+7*INT((AD30-1)/4)+CHOOSE(MOD(AD30-1,4)+1,0,2,4,5)) -> 46588 | V30: =CHOOSE(WEEKDAY(U30,2),"월","화","수","목","금","토","일") -> 화 | W30: =IFERROR(IF(INDEX($C$2:$C$799,MATCH(D30&"#"&(E30+1),$AC$2:$AC$799,0))=C30,"다음 편: ","시즌1 완결 · 시즌2 첫 편: ")&INDEX($L$2:$L$799,MATCH(D30&"#"&(E30+1),$AC$2:$AC$799,0)),"구약 트랙 완결") -> 다음 편: 이름이 바뀌다 | X30: 미착수 | Y30: 미착수 | Z30: 미착수 | AA30: 미착수 | AC30: =D30&"#"&E30 -> 구약#191 | AD30: =COUNTIFS($C$2:C30,C30,$D$2:D30,D30) -> 9
A31: 30 | B31: A0030 | C31: 2 | D31: 구약 | E31: =IF(C31=1,COUNTIFS($C$2:C31,1,$D$2:D31,D31),COUNTIFS($C$2:$C$799,1,$D$2:$D$799,D31)+COUNTIFS($C$2:C31,2,$D$2:D31,D31)) -> 192 | F31: =D31&" #"&TEXT(E31,"000") -> 구약 #192 | G31: B003 | H31: S2-L01 | I31: 창세기 | J31: 창 17:1-27 | K31: 장면 | L31: 이름이 바뀌다 | M31: 99세에 이름을 바꾼 이유 | N31: 창 17:5 | O31: 하나님의 언약은 정체성을 새롭게 합니다 | P31: 아브라함·사라 | Q31: 장막 | R31: 할례 장면 직접 묘사 금지 | S31: 시즌1 구약 #020 '하늘의 별을 세어 보라' 다음 이야기 | T31: ="["&안내!$C$5&" "&F31&"] "&L31&" | "&J31 -> [1분 성경 구약 #192] 이름이 바뀌다 | 창 17:1-27 | U31: =IF(D31="구약",IF(C31=1,안내!$C$9,안내!$C$10)+AD31-1,IF(C31=1,안내!$C$9,안내!$C$10)+7*INT((AD31-1)/4)+CHOOSE(MOD(AD31-1,4)+1,0,2,4,5)) -> 46589 | V31: =CHOOSE(WEEKDAY(U31,2),"월","화","수","목","금","토","일") -> 수 | W31: =IFERROR(IF(INDEX($C$2:$C$799,MATCH(D31&"#"&(E31+1),$AC$2:$AC$799,0))=C31,"다음 편: ","시즌1 완결 · 시즌2 첫 편: ")&INDEX($L$2:$L$799,MATCH(D31&"#"&(E31+1),$AC$2:$AC$799,0)),"구약 트랙 완결") -> 다음 편: 의인 열 명만 있다면 | X31: 미착수 | Y31: 미착수 | Z31: 미착수 | AA31: 미착수 | AC31: =D31&"#"&E31 -> 구약#192 | AD31: =COUNTIFS($C$2:C31,C31,$D$2:D31,D31) -> 10
A32: 31 | B32: A0031 | C32: 1 | D32: 구약 | E32: =IF(C32=1,COUNTIFS($C$2:C32,1,$D$2:D32,D32),COUNTIFS($C$2:$C$799,1,$D$2:$D$799,D32)+COUNTIFS($C$2:C32,2,$D$2:D32,D32)) -> 21 | F32: =D32&" #"&TEXT(E32,"000") -> 구약 #021 | G32: B004 | H32: S1-L03 | I32: 창세기 | J32: 창 18:1-15 | K32: 장면 | L32: 세 나그네 | M32: 99세 할아버지에게 아들이 생긴다고? | N32: 창 18:14 | O32: 하나님께 능하지 못한 일은 없습니다 | P32: 아브라함·사라·세 사람 | Q32: 마므레 상수리나무, 장막 | R32: 여호와의 현현은 얼굴 묘사 없이 빛과 실루엣으로 | S32: 앞에서 건너뛴 2편(시즌2): 창 16:1-16 하갈과 이스마엘, 창 17:1-27 이름이 바뀌다 → 연결 내레이션 1~2문장 필요 | T32: ="["&안내!$C$5&" "&F32&"] "&L32&" | "&J32 -> [1분 성경 구약 #021] 세 나그네 | 창 18:1-15 | U32: =IF(D32="구약",IF(C32=1,안내!$C$9,안내!$C$10)+AD32-1,IF(C32=1,안내!$C$9,안내!$C$10)+7*INT((AD32-1)/4)+CHOOSE(MOD(AD32-1,4)+1,0,2,4,5)) -> 46411 | V32: =CHOOSE(WEEKDAY(U32,2),"월","화","수","목","금","토","일") -> 일 | W32: =IFERROR(IF(INDEX($C$2:$C$799,MATCH(D32&"#"&(E32+1),$AC$2:$AC$799,0))=C32,"다음 편: ","시즌1 완결 · 시즌2 첫 편: ")&INDEX($L$2:$L$799,MATCH(D32&"#"&(E32+1),$AC$2:$AC$799,0)),"구약 트랙 완결") -> 다음 편: 웃음이라는 이름의 아이 | X32: 미착수 | Y32: 미착수 | Z32: 미착수 | AA32: 미착수 | AC32: =D32&"#"&E32 -> 구약#21 | AD32: =COUNTIFS($C$2:C32,C32,$D$2:D32,D32) -> 21
A33: 32 | B33: A0032 | C33: 2 | D33: 구약 | E33: =IF(C33=1,COUNTIFS($C$2:C33,1,$D$2:D33,D33),COUNTIFS($C$2:$C$799,1,$D$2:$D$799,D33)+COUNTIFS($C$2:C33,2,$D$2:D33,D33)) -> 193 | F33: =D33&" #"&TEXT(E33,"000") -> 구약 #193 | G33: B004 | H33: S2-L02 | I33: 창세기 | J33: 창 18:16-33 | K33: 장면 | L33: 의인 열 명만 있다면 | M33: 하나님께 여섯 번이나 다시 부탁한 사람 | N33: 창 18:25 | O33: 하나님은 의로우신 재판장이십니다 | P33: 아브라함 | Q33: 소돔이 내려다보이는 언덕 | S33: 시즌1 구약 #021 '세 나그네' 다음 이야기 | T33: ="["&안내!$C$5&" "&F33&"] "&L33&" | "&J33 -> [1분 성경 구약 #193] 의인 열 명만 있다면 | 창 18:16-33 | U33: =IF(D33="구약",IF(C33=1,안내!$C$9,안내!$C$10)+AD33-1,IF(C33=1,안내!$C$9,안내!$C$10)+7*INT((AD33-1)/4)+CHOOSE(MOD(AD33-1,4)+1,0,2,4,5)) -> 46590 | V33: =CHOOSE(WEEKDAY(U33,2),"월","화","수","목","금","토","일") -> 목 | W33: =IFERROR(IF(INDEX($C$2:$C$799,MATCH(D33&"#"&(E33+1),$AC$2:$AC$799,0))=C33,"다음 편: ","시즌1 완결 · 시즌2 첫 편: ")&INDEX($L$2:$L$799,MATCH(D33&"#"&(E33+1),$AC$2:$AC$799,0)),"구약 트랙 완결") -> 다음 편: 소돔과 고모라 | X33: 미착수 | Y33: 미착수 | Z33: 미착수 | AA33: 미착수 | AC33: =D33&"#"&E33 -> 구약#193 | AD33: =COUNTIFS($C$2:C33,C33,$D$2:D33,D33) -> 11
A34: 33 | B34: A0033 | C34: 2 | D34: 구약 | E34: =IF(C34=1,COUNTIFS($C$2:C34,1,$D$2:D34,D34),COUNTIFS($C$2:$C$799,1,$D$2:$D$799,D34)+COUNTIFS($C$2:C34,2,$D$2:D34,D34)) -> 194 | F34: =D34&" #"&TEXT(E34,"000") -> 구약 #194 | G34: B004 | H34: S2-L02 | I34: 창세기 | J34: 창 19:1-29 | K34: 장면 | L34: 소돔과 고모라 | M34: 뒤를 돌아본 여인이 소금 기둥이 되었다? | N34: 창 19:26 | O34: 심판에서 건져 주신 은혜를 붙잡아야 합니다 | P34: 롯·롯의 아내·두 천사 | Q34: 소돔 성문, 불타는 성 | R34: 성적 묘사·19:30-38 장면 제외 | S34: 시즌1 구약 #021 '세 나그네' 다음 이야기 | T34: ="["&안내!$C$5&" "&F34&"] "&L34&" | "&J34 -> [1분 성경 구약 #194] 소돔과 고모라 | 창 19:1-29 | U34: =IF(D34="구약",IF(C34=1,안내!$C$9,안내!$C$10)+AD34-1,IF(C34=1,안내!$C$9,안내!$C$10)+7*INT((AD34-1)/4)+CHOOSE(MOD(AD34-1,4)+1,0,2,4,5)) -> 46591 | V34: =CHOOSE(WEEKDAY(U34,2),"월","화","수","목","금","토","일") -> 금 | W34: =IFERROR(IF(INDEX($C$2:$C$799,MATCH(D34&"#"&(E34+1),$AC$2:$AC$799,0))=C34,"다음 편: ","시즌1 완결 · 시즌2 첫 편: ")&INDEX($L$2:$L$799,MATCH(D34&"#"&(E34+1),$AC$2:$AC$799,0)),"구약 트랙 완결") -> 다음 편: 같은 실수를 또? | X34: 미착수 | Y34: 미착수 | Z34: 미착수 | AA34: 미착수 | AC34: =D34&"#"&E34 -> 구약#194 | AD34: =COUNTIFS($C$2:C34,C34,$D$2:D34,D34) -> 12
A35: 34 | B35: A0034 | C35: 2 | D35: 구약 | E35: =IF(C35=1,COUNTIFS($C$2:C35,1,$D$2:D35,D35),COUNTIFS($C$2:$C$799,1,$D$2:$D$799,D35)+COUNTIFS($C$2:C35,2,$D$2:D35,D35)) -> 195 | F35: =D35&" #"&TEXT(E35,"000") -> 구약 #195 | G35: B004 | H35: S2-L02 | I35: 창세기 | J35: 창 20:1-18 | K35: 장면 | L35: 같은 실수를 또? | M35: 하나님이 꿈에 나타나 왕을 막으셨다 | N35: 창 20:6 | O35: 하나님은 약속의 가정을 지키십니다 | P35: 아브라함·사라·아비멜렉 | Q35: 그랄 | S35: 시즌1 구약 #021 '세 나그네' 다음 이야기 | T35: ="["&안내!$C$5&" "&F35&"] "&L35&" | "&J35 -> [1분 성경 구약 #195] 같은 실수를 또? | 창 20:1-18 | U35: =IF(D35="구약",IF(C35=1,안내!$C$9,안내!$C$10)+AD35-1,IF(C35=1,안내!$C$9,안내!$C$10)+7*INT((AD35-1)/4)+CHOOSE(MOD(AD35-1,4)+1,0,2,4,5)) -> 46592 | V35: =CHOOSE(WEEKDAY(U35,2),"월","화","수","목","금","토","일") -> 토 | W35: =IFERROR(IF(INDEX($C$2:$C$799,MATCH(D35&"#"&(E35+1),$AC$2:$AC$799,0))=C35,"다음 편: ","시즌1 완결 · 시즌2 첫 편: ")&INDEX($L$2:$L$799,MATCH(D35&"#"&(E35+1),$AC$2:$AC$799,0)),"구약 트랙 완결") -> 다음 편: 광야에서 우는 아이 | X35: 미착수 | Y35: 미착수 | Z35: 미착수 | AA35: 미착수 | AC35: =D35&"#"&E35 -> 구약#195 | AD35: =COUNTIFS($C$2:C35,C35,$D$2:D35,D35) -> 13
A36: 35 | B36: A0035 | C36: 1 | D36: 구약 | E36: =IF(C36=1,COUNTIFS($C$2:C36,1,$D$2:D36,D36),COUNTIFS($C$2:$C$799,1,$D$2:$D$799,D36)+COUNTIFS($C$2:C36,2,$D$2:D36,D36)) -> 22 | F36: =D36&" #"&TEXT(E36,"000") -> 구약 #022 | G36: B004 | H36: S1-L03 | I36: 창세기 | J36: 창 21:1-7 | K36: 장면 | L36: 웃음이라는 이름의 아이 | M36: 100세에 아버지가 된 사람 | N36: 창 21:6 | O36: 하나님은 약속하신 때에 반드시 이루십니다 | P36: 아브라함·사라·이삭 | Q36: 장막 | S36: 앞에서 건너뛴 3편(시즌2): 창 18:16-33 의인 열 명만 있다면, 창 19:1-29 소돔과 고모라, 창 20:1-18 같은 실수를 또? → 연결 내레이션 1~2문장 필요 | T36: ="["&안내!$C$5&" "&F36&"] "&L36&" | "&J36 -> [1분 성경 구약 #022] 웃음이라는 이름의 아이 | 창 21:1-7 | U36: =IF(D36="구약",IF(C36=1,안내!$C$9,안내!$C$10)+AD36-1,IF(C36=1,안내!$C$9,안내!$C$10)+7*INT((AD36-1)/4)+CHOOSE(MOD(AD36-1,4)+1,0,2,4,5)) -> 46412 | V36: =CHOOSE(WEEKDAY(U36,2),"월","화","수","목","금","토","일") -> 월 | W36: =IFERROR(IF(INDEX($C$2:$C$799,MATCH(D36&"#"&(E36+1),$AC$2:$AC$799,0))=C36,"다음 편: ","시즌1 완결 · 시즌2 첫 편: ")&INDEX($L$2:$L$799,MATCH(D36&"#"&(E36+1),$AC$2:$AC$799,0)),"구약 트랙 완결") -> 다음 편: 모리아 산 | X36: 미착수 | Y36: 미착수 | Z36: 미착수 | AA36: 미착수 | AC36: =D36&"#"&E36 -> 구약#22 | AD36: =COUNTIFS($C$2:C36,C36,$D$2:D36,D36) -> 22
A37: 36 | B37: A0036 | C37: 2 | D37: 구약 | E37: =IF(C37=1,COUNTIFS($C$2:C37,1,$D$2:D37,D37),COUNTIFS($C$2:$C$799,1,$D$2:$D$799,D37)+COUNTIFS($C$2:C37,2,$D$2:D37,D37)) -> 196 | F37: =D37&" #"&TEXT(E37,"000") -> 구약 #196 | G37: B004 | H37: S2-L02 | I37: 창세기 | J37: 창 21:8-34 | K37: 장면 | L37: 광야에서 우는 아이 | M37: 하나님이 아이의 울음소리를 들으셨다 | N37: 창 21:17 | O37: 하나님은 약한 자의 울음을 들으십니다 | P37: 하갈·이스마엘·아비멜렉 | Q37: 브엘세바 광야의 샘 | S37: 시즌1 구약 #022 '웃음이라는 이름의 아이' 다음 이야기 | T37: ="["&안내!$C$5&" "&F37&"] "&L37&" | "&J37 -> [1분 성경 구약 #196] 광야에서 우는 아이 | 창 21:8-34 | U37: =IF(D37="구약",IF(C37=1,안내!$C$9,안내!$C$10)+AD37-1,IF(C37=1,안내!$C$9,안내!$C$10)+7*INT((AD37-1)/4)+CHOOSE(MOD(AD37-1,4)+1,0,2,4,5)) -> 46593 | V37: =CHOOSE(WEEKDAY(U37,2),"월","화","수","목","금","토","일") -> 일 | W37: =IFERROR(IF(INDEX($C$2:$C$799,MATCH(D37&"#"&(E37+1),$AC$2:$AC$799,0))=C37,"다음 편: ","시즌1 완결 · 시즌2 첫 편: ")&INDEX($L$2:$L$799,MATCH(D37&"#"&(E37+1),$AC$2:$AC$799,0)),"구약 트랙 완결") -> 다음 편: 사라의 죽음과 막벨라 굴 | X37: 미착수 | Y37: 미착수 | Z37: 미착수 | AA37: 미착수 | AC37: =D37&"#"&E37 -> 구약#196 | AD37: =COUNTIFS($C$2:C37,C37,$D$2:D37,D37) -> 14
A38: 37 | B38: A0037 | C38: 1 | D38: 구약 | E38: =IF(C38=1,COUNTIFS($C$2:C38,1,$D$2:D38,D38),COUNTIFS($C$2:$C$799,1,$D$2:$D$799,D38)+COUNTIFS($C$2:C38,2,$D$2:D38,D38)) -> 23 | F38: =D38&" #"&TEXT(E38,"000") -> 구약 #023 | G38: B004 | H38: S1-L03 | I38: 창세기 | J38: 창 22:1-19 | K38: 장면 | L38: 모리아 산 | M38: 가장 사랑하는 아들을 바치라고? | N38: 창 22:14 | O38: 여호와 이레, 하나님이 준비하십니다 | P38: 아브라함·이삭 | Q38: 모리아 산, 제단, 숫양 | R38: 인신제사 정당화 아님. 대속(어린양 그리스도) 예표로 설명. 칼 장면 절제 | S38: 앞에서 건너뛴 1편(시즌2): 창 21:8-34 광야에서 우는 아이 → 연결 내레이션 1~2문장 필요 | T38: ="["&안내!$C$5&" "&F38&"] "&L38&" | "&J38 -> [1분 성경 구약 #023] 모리아 산 | 창 22:1-19 | U38: =IF(D38="구약",IF(C38=1,안내!$C$9,안내!$C$10)+AD38-1,IF(C38=1,안내!$C$9,안내!$C$10)+7*INT((AD38-1)/4)+CHOOSE(MOD(AD38-1,4)+1,0,2,4,5)) -> 46413 | V38: =CHOOSE(WEEKDAY(U38,2),"월","화","수","목","금","토","일") -> 화 | W38: =IFERROR(IF(INDEX($C$2:$C$799,MATCH(D38&"#"&(E38+1),$AC$2:$AC$799,0))=C38,"다음 편: ","시즌1 완결 · 시즌2 첫 편: ")&INDEX($L$2:$L$799,MATCH(D38&"#"&(E38+1),$AC$2:$AC$799,0)),"구약 트랙 완결") -> 다음 편: 낙타에게 물을 주는 여인 | X38: 미착수 | Y38: 미착수 | Z38: 미착수 | AA38: 미착수 | AC38: =D38&"#"&E38 -> 구약#23 | AD38: =COUNTIFS($C$2:C38,C38,$D$2:D38,D38) -> 23
A39: 38 | B39: A0038 | C39: 2 | D39: 구약 | E39: =IF(C39=1,COUNTIFS($C$2:C39,1,$D$2:D39,D39),COUNTIFS($C$2:$C$799,1,$D$2:$D$799,D39)+COUNTIFS($C$2:C39,2,$D$2:D39,D39)) -> 197 | F39: =D39&" #"&TEXT(E39,"000") -> 구약 #197 | G39: B004 | H39: S2-L02 | I39: 창세기 | J39: 창 22:20-23:20 | K39: 장면 | L39: 사라의 죽음과 막벨라 굴 | M39: 약속의 땅에서 처음 산 땅이 무덤? | N39: 창 23:19 | O39: 약속을 믿는 사람은 죽음 앞에서도 소망이 있습니다 | P39: 아브라함·헷 족속 에브론 | Q39: 헤브론 막벨라 굴 | S39: 시즌1 구약 #023 '모리아 산' 다음 이야기 | T39: ="["&안내!$C$5&" "&F39&"] "&L39&" | "&J39 -> [1분 성경 구약 #197] 사라의 죽음과 막벨라 굴 | 창 22:20-23:20 | U39: =IF(D39="구약",IF(C39=1,안내!$C$9,안내!$C$10)+AD39-1,IF(C39=1,안내!$C$9,안내!$C$10)+7*INT((AD39-1)/4)+CHOOSE(MOD(AD39-1,4)+1,0,2,4,5)) -> 46594 | V39: =CHOOSE(WEEKDAY(U39,2),"월","화","수","목","금","토","일") -> 월 | W39: =IFERROR(IF(INDEX($C$2:$C$799,MATCH(D39&"#"&(E39+1),$AC$2:$AC$799,0))=C39,"다음 편: ","시즌1 완결 · 시즌2 첫 편: ")&INDEX($L$2:$L$799,MATCH(D39&"#"&(E39+1),$AC$2:$AC$799,0)),"구약 트랙 완결") -> 다음 편: 가겠나이다 | X39: 미착수 | Y39: 미착수 | Z39: 미착수 | AA39: 미착수 | AC39: =D39&"#"&E39 -> 구약#197 | AD39: =COUNTIFS($C$2:C39,C39,$D$2:D39,D39) -> 15
A40: 39 | B40: A0039 | C40: 1 | D40: 구약 | E40: =IF(C40=1,COUNTIFS($C$2:C40,1,$D$2:D40,D40),COUNTIFS($C$2:$C$799,1,$D$2:$D$799,D40)+COUNTIFS($C$2:C40,2,$D$2:D40,D40)) -> 24 | F40: =D40&" #"&TEXT(E40,"000") -> 구약 #024 | G40: B005 | H40: S1-L03 | I40: 창세기 | J40: 창 24:1-27 | K40: 장면 | L40: 낙타에게 물을 주는 여인 | M40: 기도가 끝나기도 전에 응답이 왔다? | N40: 창 24:12 | O40: 하나님은 기도하는 사람의 길을 인도하십니다 | P40: 아브라함의 종·리브가 | Q40: 나홀 성 우물가 | S40: 앞에서 건너뛴 1편(시즌2): 창 22:20-23:20 사라의 죽음과 막벨라 굴 → 연결 내레이션 1~2문장 필요 | T40: ="["&안내!$C$5&" "&F40&"] "&L40&" | "&J40 -> [1분 성경 구약 #024] 낙타에게 물을 주는 여인 | 창 24:1-27 | U40: =IF(D40="구약",IF(C40=1,안내!$C$9,안내!$C$10)+AD40-1,IF(C40=1,안내!$C$9,안내!$C$10)+7*INT((AD40-1)/4)+CHOOSE(MOD(AD40-1,4)+1,0,2,4,5)) -> 46414 | V40: =CHOOSE(WEEKDAY(U40,2),"월","화","수","목","금","토","일") -> 수 | W40: =IFERROR(IF(INDEX($C$2:$C$799,MATCH(D40&"#"&(E40+1),$AC$2:$AC$799,0))=C40,"다음 편: ","시즌1 완결 · 시즌2 첫 편: ")&INDEX($L$2:$L$799,MATCH(D40&"#"&(E40+1),$AC$2:$AC$799,0)),"구약 트랙 완결") -> 다음 편: 배 속에서부터 싸운 쌍둥이 | X40: 미착수 | Y40: 미착수 | Z40: 미착수 | AA40: 미착수 | AC40: =D40&"#"&E40 -> 구약#24 | AD40: =COUNTIFS($C$2:C40,C40,$D$2:D40,D40) -> 24
...

Sheet 롱폼_시즌별
A1: 순번 | B1: 롱폼코드 | C1: 시즌 | D1: 트랙 | E1: 롱폼 제목 | F1: 포함 통합본 B | G1: 본문 범위 | H1: A 편수 | I1: 예상 길이(초) | J1: 예상 길이(분) | K1: 첫 회차 | L1: 마지막 회차 | M1: 진행자 인트로 질문(삶의 고민) | N1: 그리스도 연결점 | O1: 핵심 교리 | P1: 공개 예정일 | Q1: 요일 | R1: 대본 | S1: 교리감수 | T1: 영상 | U1: 업로드 | V1: 비고
A2: 1 | B2: S1-L01 | C2: 1 | D2: 구약 | E2: 창조와 타락 | F2: B001 | G2: 창 1:1~3:24 | H2: =COUNTIF(A타입_제작표!$H$2:$H$799,B2) -> 10 | I2: =H2*안내!$C$7+안내!$C$8 -> 640 | J2: =ROUND(I2/60,1) -> 10.7 | K2: =D2&" #"&TEXT(_xlfn.MINIFS(A타입_제작표!$E$2:$E$799,A타입_제작표!$H$2:$H$799,B2),"000") -> 구약 #001 | L2: =D2&" #"&TEXT(_xlfn.MAXIFS(A타입_제작표!$E$2:$E$799,A타입_제작표!$H$2:$H$799,B2),"000") -> 구약 #010 | M2: 세상은 처음에 어떻게 시작됐을까? | N2: 3:15 여자의 후손 약속(원시복음) → 사탄을 이기실 그리스도 | O2: 창조주 하나님, 하나님의 형상, 원죄, 은혜의 약속 | P2: =_xlfn.MAXIFS(A타입_제작표!$U$2:$U$799,A타입_제작표!$H$2:$H$799,B2)+1 -> 46401 | Q2: =CHOOSE(WEEKDAY(P2,2),"월","화","수","목","금","토","일") -> 목 | R2: 미착수 | S2: 미착수 | T2: 미착수 | U2: 미착수
A3: 2 | B3: S1-L02 | C3: 1 | D3: 구약 | E3: 가인부터 바벨까지 | F3: B002 | G3: 창 4:1~11:9 | H3: =COUNTIF(A타입_제작표!$H$2:$H$799,B3) -> 8 | I3: =H3*안내!$C$7+안내!$C$8 -> 536 | J3: =ROUND(I3/60,1) -> 8.9 | K3: =D3&" #"&TEXT(_xlfn.MINIFS(A타입_제작표!$E$2:$E$799,A타입_제작표!$H$2:$H$799,B3),"000") -> 구약 #011 | L3: =D3&" #"&TEXT(_xlfn.MAXIFS(A타입_제작표!$E$2:$E$799,A타입_제작표!$H$2:$H$799,B3),"000") -> 구약 #018 | M3: 사람은 왜 자꾸 하나님을 떠날까? | N3: 노아의 방주 → 심판에서 건지는 구원의 방주이신 그리스도(벧전 3:20-21) | O3: 죄의 확산, 심판과 은혜, 언약 | P3: =_xlfn.MAXIFS(A타입_제작표!$U$2:$U$799,A타입_제작표!$H$2:$H$799,B3)+1 -> 46409 | Q3: =CHOOSE(WEEKDAY(P3,2),"월","화","수","목","금","토","일") -> 금 | R3: 미착수 | S3: 미착수 | T3: 미착수 | U3: 미착수
A4: 3 | B4: S1-L03 | C4: 1 | D4: 구약 | E4: 아브라함① 부르심과 언약 ~ 이삭과 리브가 | F4: B003, B004, B005 | G4: 창 12:1~25:34 | H4: =COUNTIF(A타입_제작표!$H$2:$H$799,B4) -> 8 | I4: =H4*안내!$C$7+안내!$C$8 -> 536 | J4: =ROUND(I4/60,1) -> 8.9 | K4: =D4&" #"&TEXT(_xlfn.MINIFS(A타입_제작표!$E$2:$E$799,A타입_제작표!$H$2:$H$799,B4),"000") -> 구약 #019 | L4: =D4&" #"&TEXT(_xlfn.MAXIFS(A타입_제작표!$E$2:$E$799,A타입_제작표!$H$2:$H$799,B4),"000") -> 구약 #026 | M4: 확실한 게 하나도 없을 때 떠날 수 있을까? | N4: 아브라함의 씨 → 모든 민족이 복을 받을 그리스도(갈 3:16) 모리아 산의 숫양 → 아들을 대신 내어주신 하나님, 십자가의 예표 약속의 아들 이삭 → 약속대로 오신 참 아들 그리스도 | O4: 이신칭의(15:6), 언약, 하나님의 신실하심 / 하나님의 주권, 중보, 대속의 예표 | P4: =_xlfn.MAXIFS(A타입_제작표!$U$2:$U$799,A타입_제작표!$H$2:$H$799,B4)+1 -> 46417 | Q4: =CHOOSE(WEEKDAY(P4,2),"월","화","수","목","금","토","일") -> 토 | R4: 미착수 | S4: 미착수 | T4: 미착수 | U4: 미착수
A5: 4 | B5: S1-L04 | C5: 1 | D5: 구약 | E5: 야곱① 축복을 훔친 사람 ~ 요셉① 구덩이에서 왕궁으로 | F5: B006, B007, B008 | G5: 창 27:1~41:57 | H5: =COUNTIF(A타입_제작표!$H$2:$H$799,B5) -> 11 | I5: =H5*안내!$C$7+안내!$C$8 -> 692 | J5: =ROUND(I5/60,1) -> 11.5 | K5: =D5&" #"&TEXT(_xlfn.MINIFS(A타입_제작표!$E$2:$E$799,A타입_제작표!$H$2:$H$799,B5),"000") -> 구약 #027 | L5: =D5&" #"&TEXT(_xlfn.MAXIFS(A타입_제작표!$E$2:$E$799,A타입_제작표!$H$2:$H$799,B5),"000") -> 구약 #037 | M5: 원하는 것을 위해 꾀를 써도 될까? | N5: 벧엘의 사다리 → 하늘과 땅을 잇는 인자(요 1:51) 씨름 끝에 받은 새 이름 → 그리스도 안에서 새 사람 버림받았다가 높여져 세상을 살린 요셉 → 그리스도의 예표 | O5: 은혜의 선택, 하나님의 동행, 죄의 결과 / 기도, 화해, 회개와 새 출발 | P5: =_xlfn.MAXIFS(A타입_제작표!$U$2:$U$799,A타입_제작표!$H$2:$H$799,B5)+1 -> 46428 | Q5: =CHOOSE(WEEKDAY(P5,2),"월","화","수","목","금","토","일") -> 수 | R5: 미착수 | S5: 미착수 | T5: 미착수 | U5: 미착수
A6: 5 | B6: S1-L05 | C6: 1 | D6: 구약 | E6: 요셉② 용서와 화해 ~ 모세의 탄생과 부르심 | F6: B009, B010 | G6: 창 42:1~출 5:23 | H6: =COUNTIF(A타입_제작표!$H$2:$H$799,B6) -> 11 | I6: =H6*안내!$C$7+안내!$C$8 -> 692 | J6: =ROUND(I6/60,1) -> 11.5 | K6: =D6&" #"&TEXT(_xlfn.MINIFS(A타입_제작표!$E$2:$E$799,A타입_제작표!$H$2:$H$799,B6),"000") -> 구약 #038 | L6: =D6&" #"&TEXT(_xlfn.MAXIFS(A타입_제작표!$E$2:$E$799,A타입_제작표!$H$2:$H$799,B6),"000") -> 구약 #048 | M6: 나에게 상처 준 사람을 용서할 수 있을까? | N6: 대신 종이 되겠다는 유다 → 우리 대신 죗값을 치르신 그리스도 모세 → 백성을 구원하는 더 큰 선지자 그리스도(신 18:15, 히 3) | O6: 용서, 섭리(50:20), 메시아 약속(49:10) / 여호와(스스로 있는 자), 언약을 기억하시는 하나님 | P6: =_xlfn.MAXIFS(A타입_제작표!$U$2:$U$799,A타입_제작표!$H$2:$H$799,B6)+1 -> 46439 | Q6: =CHOOSE(WEEKDAY(P6,2),"월","화","수","목","금","토","일") -> 일 | R6: 미착수 | S6: 미착수 | T6: 미착수 | U6: 미착수
A7: 6 | B7: S1-L06 | C7: 1 | D7: 구약 | E7: 열 가지 재앙과 유월절 ~ 홍해와 광야 | F7: B011, B012 | G7: 출 7:1~17:16 | H7: =COUNTIF(A타입_제작표!$H$2:$H$799,B7) -> 11 | I7: =H7*안내!$C$7+안내!$C$8 -> 692 | J7: =ROUND(I7/60,1) -> 11.5 | K7: =D7&" #"&TEXT(_xlfn.MINIFS(A타입_제작표!$E$2:$E$799,A타입_제작표!$H$2:$H$799,B7),"000") -> 구약 #049 | L7: =D7&" #"&TEXT(_xlfn.MAXIFS(A타입_제작표!$E$2:$E$799,A타입_제작표!$H$2:$H$799,B7),"000") -> 구약 #059 | M7: 하나님이 정말 이 세상을 다스리고 계실까? | N7: 유월절 어린양의 피 → 우리의 유월절 양 그리스도(고전 5:7) 하늘의 만나와 반석의 물 → 생명의 떡이요 생수이신 그리스도(요 6, 고전 10:4) | O7: 하나님의 주권, 심판, 대속의 피 / 구원, 공급하시는 하나님, 원망과 믿음 | P7: =_xlfn.MAXIFS(A타입_제작표!$U$2:$U$799,A타입_제작표!$H$2:$H$799,B7)+1 -> 46450 | Q7: =CHOOSE(WEEKDAY(P7,2),"월","화","수","목","금","토","일") -> 목 | R7: 미착수 | S7: 미착수 | T7: 미착수 | U7: 미착수
A8: 7 | B8: S1-L07 | C8: 1 | D8: 구약 | E8: 시내산 언약과 성막 ~ 거룩한 하나님께 나아가는 길 | F8: B013, B014, B015 | G8: 출 19:1~레 16:34 | H8: =COUNTIF(A타입_제작표!$H$2:$H$799,B8) -> 7 | I8: =H8*안내!$C$7+안내!$C$8 -> 484 | J8: =ROUND(I8/60,1) -> 8.1 | K8: =D8&" #"&TEXT(_xlfn.MINIFS(A타입_제작표!$E$2:$E$799,A타입_제작표!$H$2:$H$799,B8),"000") -> 구약 #060 | L8: =D8&" #"&TEXT(_xlfn.MAXIFS(A타입_제작표!$E$2:$E$799,A타입_제작표!$H$2:$H$799,B8),"000") -> 구약 #066 | M8: 하나님은 왜 규칙을 주셨을까? | N8: 율법의 완성자 그리스도(마 5:17), 성막 = 우리 가운데 거하신 말씀(요 1:14) 중보자 모세 → 우리를 위해 간구하시는 그리스도(히 7:25) 모든 제사의 완성 = 단번에 드려진 그리스도의 제사(히 10:10) | O8: 율법은 구원받은 백성의 삶의 규칙, 하나님의 임재 / 우상숭배, 중보, 회복, 하나님의 영광 | P8: =_xlfn.MAXIFS(A타입_제작표!$U$2:$U$799,A타입_제작표!$H$2:$H$799,B8)+1 -> 46457 | Q8: =CHOOSE(WEEKDAY(P8,2),"월","화","수","목","금","토","일") -> 목 | R8: 미착수 | S8: 미착수 | T8: 미착수 | U8: 미착수
A9: 8 | B9: S1-L08 | C9: 1 | D9: 구약 | E9: 광야로 출발한 군대 ~ 요단을 건너 여리고로 | F9: B016, B017, B018, B019 | G9: 민 13:1~수 7:26 | H9: =COUNTIF(A타입_제작표!$H$2:$H$799,B9) -> 11 | I9: =H9*안내!$C$7+안내!$C$8 -> 692 | J9: =ROUND(I9/60,1) -> 11.5 | K9: =D9&" #"&TEXT(_xlfn.MINIFS(A타입_제작표!$E$2:$E$799,A타입_제작표!$H$2:$H$799,B9),"000") -> 구약 #067 | L9: =D9&" #"&TEXT(_xlfn.MAXIFS(A타입_제작표!$E$2:$E$799,A타입_제작표!$H$2:$H$799,B9),"000") -> 구약 #077 | M9: 함께 사는 공동체, 원망은 어디서 시작될까? | N9: 광야의 구름 기둥 → 우리를 인도하시는 성령, 놋뱀 → 십자가(요 3:14) 놋뱀을 바라보면 산다 → 십자가의 그리스도를 바라보면 산다(요 3:14-15) 모세 같은 선지자(18:15) → 그리스도, 마음의 할례 → 새 언약 여호수아(예수와 같은 이름) → 참 안식으로 이끄시는 그리스도(히 4:8), 라합의 붉은 줄 → 보혈 | O9: 인도하심, 불신앙의 결과, 남은 자의 믿음 / 하나님의 신실하심, 다음 세대, 믿음의 바라봄 | P9: =_xlfn.MAXIFS(A타입_제작표!$U$2:$U$799,A타입_제작표!$H$2:$H$799,B9)+1 -> 46468 | Q9: =CHOOSE(WEEKDAY(P9,2),"월","화","수","목","금","토","일") -> 월 | R9: 미착수 | S9: 미착수 | T9: 미착수 | U9: 미착수
A10: 9 | B10: S1-L09 | C10: 1 | D10: 구약 | E10: 약속의 땅을 나누다 ~ 사사들의 시대② | F10: B020, B021, B022 | G10: 수 10:1~삿 16:31 | H10: =COUNTIF(A타입_제작표!$H$2:$H$799,B10) -> 8 | I10: =H10*안내!$C$7+안내!$C$8 -> 536 | J10: =ROUND(I10/60,1) -> 8.9 | K10: =D10&" #"&TEXT(_xlfn.MINIFS(A타입_제작표!$E$2:$E$799,A타입_제작표!$H$2:$H$799,B10),"000") -> 구약 #078 | L10: =D10&" #"&TEXT(_xlfn.MAXIFS(A타입_제작표!$E$2:$E$799,A타입_제작표!$H$2:$H$799,B10),"000") -> 구약 #085 | M10: 하나님의 약속은 정말 다 이루어질까? | N10: 하나님의 약속 성취(21:45) → 모든 약속의 '예'가 되신 그리스도(고후 1:20) 연약한 구원자들 → 완전한 구원자 그리스도 나실인 삼손의 죽음으로 이룬 승리 → 죽음으로 승리하신 그리스도 | O10: 하나님께 묻는 삶, 약속 성취, 언약 갱신 / 죄와 은혜의 반복, 하나님이 세우시는 구원자 | P10: =_xlfn.MAXIFS(A타입_제작표!$U$2:$U$799,A타입_제작표!$H$2:$H$799,B10)+1 -> 46476 | Q10: =CHOOSE(WEEKDAY(P10,2),"월","화","수","목","금","토","일") -> 화 | R10: 미착수 | S10: 미착수 | T10: 미착수 | U10: 미착수
A11: 10 | B11: S1-L10 | C11: 1 | D11: 구약 | E11: 룻과 한나: 왕을 기다리는 사람들 ~ 왕을 원한 백성 | F11: B023, B024 | G11: 룻 1:1~삼상 15:35 | H11: =COUNTIF(A타입_제작표!$H$2:$H$799,B11) -> 10 | I11: =H11*안내!$C$7+안내!$C$8 -> 640 | J11: =ROUND(I11/60,1) -> 10.7 | K11: =D11&" #"&TEXT(_xlfn.MINIFS(A타입_제작표!$E$2:$E$799,A타입_제작표!$H$2:$H$799,B11),"000") -> 구약 #086 | L11: =D11&" #"&TEXT(_xlfn.MAXIFS(A타입_제작표!$E$2:$E$799,A타입_제작표!$H$2:$H$799,B11),"000") -> 구약 #095 | M11: 가장 절망적일 때 하나님은 무엇을 하고 계실까? | N11: 기업 무를 자 보아스 → 우리를 값 주고 사신 그리스도 사람이 원한 왕 사울 → 하나님이 세우신 참 왕 그리스도 | O11: 섭리, 이방인을 향한 은혜, 기도 응답 / 하나님의 왕 되심, 순종, 에벤에셀 | P11: =_xlfn.MAXIFS(A타입_제작표!$U$2:$U$799,A타입_제작표!$H$2:$H$799,B11)+1 -> 46486 | Q11: =CHOOSE(WEEKDAY(P11,2),"월","화","수","목","금","토","일") -> 금 | R11: 미착수 | S11: 미착수 | T11: 미착수 | U11: 미착수
A12: 11 | B12: S1-L11 | C12: 1 | D12: 구약 | E12: 목동 다윗과 사울 왕 ~ 다윗 왕국 | F12: B025, B027 | G12: 삼상 16:1~삼하 9:13 | H12: =COUNTIF(A타입_제작표!$H$2:$H$799,B12) -> 9 | I12: =H12*안내!$C$7+안내!$C$8 -> 588 | J12: =ROUND(I12/60,1) -> 9.8 | K12: =D12&" #"&TEXT(_xlfn.MINIFS(A타입_제작표!$E$2:$E$799,A타입_제작표!$H$2:$H$799,B12),"000") -> 구약 #096 | L12: =D12&" #"&TEXT(_xlfn.MAXIFS(A타입_제작표!$E$2:$E$799,A타입_제작표!$H$2:$H$799,B12),"000") -> 구약 #104 | M12: 억울하게 미움받을 때 어떻게 해야 할까? | N12: 기름부음 받은 목자 다윗 → 참 목자요 왕이신 그리스도 다윗 언약(7:16) → 영원한 다윗의 자손 그리스도(눅 1:32-33) | O12: 중심을 보시는 하나님, 믿음의 용기, 기다림 / 언약, 예배의 기쁨, 은혜(므비보셋) | P12: =_xlfn.MAXIFS(A타입_제작표!$U$2:$U$799,A타입_제작표!$H$2:$H$799,B12)+1 -> 46495 | Q12: =CHOOSE(WEEKDAY(P12,2),"월","화","수","목","금","토","일") -> 일 | R12: 미착수 | S12: 미착수 | T12: 미착수 | U12: 미착수
A13: 12 | B13: S1-L12 | C13: 1 | D13: 구약 | E13: 다윗의 죄와 회복 ~ 지혜의 왕 솔로몬 | F13: B028, B029 | G13: 삼하 11:1~왕상 11:43 | H13: =COUNTIF(A타입_제작표!$H$2:$H$799,B13) -> 9 | I13: =H13*안내!$C$7+안내!$C$8 -> 588 | J13: =ROUND(I13/60,1) -> 9.8 | K13: =D13&" #"&TEXT(_xlfn.MINIFS(A타입_제작표!$E$2:$E$799,A타입_제작표!$H$2:$H$799,B13),"000") -> 구약 #105 | L13: =D13&" #"&TEXT(_xlfn.MAXIFS(A타입_제작표!$E$2:$E$799,A타입_제작표!$H$2:$H$799,B13),"000") -> 구약 #113 | M13: 큰 잘못을 저지른 뒤에도 돌아갈 수 있을까? | N13: 죄인을 용서하시는 하나님(시 51) → 십자가의 용서 솔로몬보다 더 큰 이(마 12:42) 그리스도, 성전 → 참 성전이신 그리스도(요 2:21) | O13: 죄의 결과, 회개, 용서받은 자의 고난 / 지혜, 성전과 임재, 마음을 지키지 못한 실패 | P13: =_xlfn.MAXIFS(A타입_제작표!$U$2:$U$799,A타입_제작표!$H$2:$H$799,B13)+1 -> 46504 | Q13: =CHOOSE(WEEKDAY(P13,2),"월","화","수","목","금","토","일") -> 화 | R13: 미착수 | S13: 미착수 | T13: 미착수 | U13: 미착수
... A86: 85 | B86: S2-L54 | C86: 2 | D86: 신약 | E86: 요한계시록② 새 하늘과 새 땅 | F86: B084 | G86: 계 12:1~20:15 | H86: =COUNTIF(A타입_제작표!$H$2:$H$799,B86) -> 7 | I86: =H86*안내!$C$7+안내!$C$8 -> 484 | J86: =ROUND(I86/60,1) -> 8.1 | K86: =D86&" #"&TEXT(_xlfn.MINIFS(A타입_제작표!$E$2:$E$799,A타입_제작표!$H$2:$H$799,B86),"000") -> 신약 #271 | L86: =D86&" #"&TEXT(_xlfn.MAXIFS(A타입_제작표!$E$2:$E$799,A타입_제작표!$H$2:$H$799,B86),"000") -> 신약 #277 | M86: 이 세상의 끝은 어떻게 될까? | N86: 어린양의 혼인 잔치, 백마 탄 왕, 새 예루살렘의 등불이신 어린양 | O86: 최후 승리, 심판, 새 창조, 재림 소망 | P86: =_xlfn.MAXIFS(A타입_제작표!$U$2:$U$799,A타입_제작표!$H$2:$H$799,B86)+1 -> 46882 | Q86: =CHOOSE(WEEKDAY(P86,2),"월","화","수","목","금","토","일") -> 화 | R86: 미착수 | S86: 미착수 | T86: 미착수 | U86: 미착수

Sheet 롱폼_통합본
A1: 순번 | B1: B코드 | C1: 롱폼 제목 | D1: 포함 책 | E1: 본문 범위 | F1: A 편수 | G1: 그중 시즌1 | H1: 예상 길이(초) | I1: 예상 길이(분) | J1: 첫 A코드 | K1: 마지막 A코드 | L1: 진행자 인트로 질문(삶의 고민) | M1: 그리스도 연결점 | N1: 핵심 교리 | O1: 전체 주의 | P1: 모든 편 공개 완료일 | Q1: 대본 | R1: 교리감수 | S1: 영상 | T1: 업로드 | U1: 비고
A2: 1 | B2: B001 | C2: 창조와 타락 | D2: 창세기 | E2: 창 1:1~3:24 | F2: =COUNTIF(A타입_제작표!$G$2:$G$799,B2) -> 10 | G2: =COUNTIFS(A타입_제작표!$G$2:$G$799,B2,A타입_제작표!$C$2:$C$799,1) -> 10 | H2: =F2*안내!$C$7+안내!$C$8 -> 640 | I2: =ROUND(H2/60,1) -> 10.7 | J2: =INDEX(A타입_제작표!$B$2:$B$799,MATCH(B2,A타입_제작표!$G$2:$G$799,0)) -> A0001 | K2: =INDEX(A타입_제작표!$B$2:$B$799,MATCH(B2,A타입_제작표!$G$2:$G$799,0)+F2-1) -> A0010 | L2: 세상은 처음에 어떻게 시작됐을까? | M2: 3:15 여자의 후손 약속(원시복음) → 사탄을 이기실 그리스도 | N2: 창조주 하나님, 하나님의 형상, 원죄, 은혜의 약속 | P2: =_xlfn.MAXIFS(A타입_제작표!$U$2:$U$799,A타입_제작표!$G$2:$G$799,B2) -> 46400 | Q2: 미착수 | R2: 미착수 | S2: 미착수 | T2: 미착수
A3: 2 | B3: B002 | C3: 가인부터 바벨까지 | D3: 창세기 | E3: 창 4:1~11:32 | F3: =COUNTIF(A타입_제작표!$G$2:$G$799,B3) -> 13 | G3: =COUNTIFS(A타입_제작표!$G$2:$G$799,B3,A타입_제작표!$C$2:$C$799,1) -> 8 | H3: =F3*안내!$C$7+안내!$C$8 -> 796 | I3: =ROUND(H3/60,1) -> 13.3 | J3: =INDEX(A타입_제작표!$B$2:$B$799,MATCH(B3,A타입_제작표!$G$2:$G$799,0)) -> A0011 | K3: =INDEX(A타입_제작표!$B$2:$B$799,MATCH(B3,A타입_제작표!$G$2:$G$799,0)+F3-1) -> A0023 | L3: 사람은 왜 자꾸 하나님을 떠날까? | M3: 노아의 방주 → 심판에서 건지는 구원의 방주이신 그리스도(벧전 3:20-21) | N3: 죄의 확산, 심판과 은혜, 언약 | P3: =_xlfn.MAXIFS(A타입_제작표!$U$2:$U$799,A타입_제작표!$G$2:$G$799,B3) -> 46584 | Q3: 미착수 | R3: 미착수 | S3: 미착수 | T3: 미착수
A4: 3 | B4: B003 | C4: 아브라함① 부르심과 언약 | D4: 창세기 | E4: 창 12:1~17:27 | F4: =COUNTIF(A타입_제작표!$G$2:$G$799,B4) -> 7 | G4: =COUNTIFS(A타입_제작표!$G$2:$G$799,B4,A타입_제작표!$C$2:$C$799,1) -> 2 | H4: =F4*안내!$C$7+안내!$C$8 -> 484 | I4: =ROUND(H4/60,1) -> 8.1 | J4: =INDEX(A타입_제작표!$B$2:$B$799,MATCH(B4,A타입_제작표!$G$2:$G$799,0)) -> A0024 | K4: =INDEX(A타입_제작표!$B$2:$B$799,MATCH(B4,A타입_제작표!$G$2:$G$799,0)+F4-1) -> A0030 | L4: 확실한 게 하나도 없을 때 떠날 수 있을까? | M4: 아브라함의 씨 → 모든 민족이 복을 받을 그리스도(갈 3:16) | N4: 이신칭의(15:6), 언약, 하나님의 신실하심 | P4: =_xlfn.MAXIFS(A타입_제작표!$U$2:$U$799,A타입_제작표!$G$2:$G$799,B4) -> 46589 | Q4: 미착수 | R4: 미착수 | S4: 미착수 | T4: 미착수
A5: 4 | B5: B004 | C5: 아브라함② 시험과 약속의 아들 | D5: 창세기 | E5: 창 18:1~23:20 | F5: =COUNTIF(A타입_제작표!$G$2:$G$799,B5) -> 8 | G5: =COUNTIFS(A타입_제작표!$G$2:$G$799,B5,A타입_제작표!$C$2:$C$799,1) -> 3 | H5: =F5*안내!$C$7+안내!$C$8 -> 536 | I5: =ROUND(H5/60,1) -> 8.9 | J5: =INDEX(A타입_제작표!$B$2:$B$799,MATCH(B5,A타입_제작표!$G$2:$G$799,0)) -> A0031 | K5: =INDEX(A타입_제작표!$B$2:$B$799,MATCH(B5,A타입_제작표!$G$2:$G$799,0)+F5-1) -> A0038 | L5: 정말 소중한 것을 하나님께 맡길 수 있을까? | M5: 모리아 산의 숫양 → 아들을 대신 내어주신 하나님, 십자가의 예표 | N5: 하나님의 주권, 중보, 대속의 예표 | P5: =_xlfn.MAXIFS(A타입_제작표!$U$2:$U$799,A타입_제작표!$G$2:$G$799,B5) -> 46594 | Q5: 미착수 | R5: 미착수 | S5: 미착수 | T5: 미착수
A6: 5 | B6: B005 | C6: 이삭과 리브가 | D6: 창세기 | E6: 창 24:1~26:35 | F6: =COUNTIF(A타입_제작표!$G$2:$G$799,B6) -> 7 | G6: =COUNTIFS(A타입_제작표!$G$2:$G$799,B6,A타입_제작표!$C$2:$C$799,1) -> 3 | H6: =F6*안내!$C$7+안내!$C$8 -> 484 | I6: =ROUND(H6/60,1) -> 8.1 | J6: =INDEX(A타입_제작표!$B$2:$B$799,MATCH(B6,A타입_제작표!$G$2:$G$799,0)) -> A0039 | K6: =INDEX(A타입_제작표!$B$2:$B$799,MATCH(B6,A타입_제작표!$G$2:$G$799,0)+F6-1) -> A0045 | L6: 하나님의 인도하심은 어떻게 알 수 있을까? | M6: 약속의 아들 이삭 → 약속대로 오신 참 아들 그리스도 | N6: 섭리, 기도 응답, 선택(롬 9:10-13) | P6: =_xlfn.MAXIFS(A타입_제작표!$U$2:$U$799,A타입_제작표!$G$2:$G$799,B6) -> 46598 | Q6: 미착수 | R6: 미착수 | S6: 미착수 | T6: 미착수
A7: 6 | B7: B006 | C7: 야곱① 축복을 훔친 사람 | D7: 창세기 | E7: 창 27:1~31:55 | F7: =COUNTIF(A타입_제작표!$G$2:$G$799,B7) -> 8 | G7: =COUNTIFS(A타입_제작표!$G$2:$G$799,B7,A타입_제작표!$C$2:$C$799,1) -> 3 | H7: =F7*안내!$C$7+안내!$C$8 -> 536 | I7: =ROUND(H7/60,1) -> 8.9 | J7: =INDEX(A타입_제작표!$B$2:$B$799,MATCH(B7,A타입_제작표!$G$2:$G$799,0)) -> A0046 | K7: =INDEX(A타입_제작표!$B$2:$B$799,MATCH(B7,A타입_제작표!$G$2:$G$799,0)+F7-1) -> A0053 | L7: 원하는 것을 위해 꾀를 써도 될까? | M7: 벧엘의 사다리 → 하늘과 땅을 잇는 인자(요 1:51) | N7: 은혜의 선택, 하나님의 동행, 죄의 결과 | P7: =_xlfn.MAXIFS(A타입_제작표!$U$2:$U$799,A타입_제작표!$G$2:$G$799,B7) -> 46603 | Q7: 미착수 | R7: 미착수 | S7: 미착수 | T7: 미착수
A8: 7 | B8: B007 | C8: 야곱② 이스라엘이 되다 | D8: 창세기 | E8: 창 32:1~36:43 | F8: =COUNTIF(A타입_제작표!$G$2:$G$799,B8) -> 7 | G8: =COUNTIFS(A타입_제작표!$G$2:$G$799,B8,A타입_제작표!$C$2:$C$799,1) -> 2 | H8: =F8*안내!$C$7+안내!$C$8 -> 484 | I8: =ROUND(H8/60,1) -> 8.1 | J8: =INDEX(A타입_제작표!$B$2:$B$799,MATCH(B8,A타입_제작표!$G$2:$G$799,0)) -> A0054 | K8: =INDEX(A타입_제작표!$B$2:$B$799,MATCH(B8,A타입_제작표!$G$2:$G$799,0)+F8-1) -> A0060 | L8: 두려운 사람을 다시 만나야 할 때 어떻게 할까? | M8: 씨름 끝에 받은 새 이름 → 그리스도 안에서 새 사람 | N8: 기도, 화해, 회개와 새 출발 | P8: =_xlfn.MAXIFS(A타입_제작표!$U$2:$U$799,A타입_제작표!$G$2:$G$799,B8) -> 46608 | Q8: 미착수 | R8: 미착수 | S8: 미착수 | T8: 미착수
