Workbook

Sheet 안내
A1: 프로젝트2 · 말씀 숏폼 제작표
A2: 성경 66권 핵심 구절 728편을 6개월에 · 구약/신약 트랙 · 성경 본문: 개역한글판 | 작성일 2026-10-27
A4: 제작 변수 (노란 칸만 수정하세요)
A5: 말씀 시리즈 이름(가칭) | C5: 오늘의 말씀 | D5: 같은 채널 안의 재생목록 이름. 제목·해시태그에 반영
A6: 시작일 | C6: 46388 | D6: 예시 날짜입니다. 프로젝트1과 상관없이 정하면 됩니다
A7: 트랙별 하루 편수 | C7: 2 | D7: 구약·신약 각각. 2편이면 하루 총 4편
A8: 구약 1번째 업로드 시간 | C8: 06:30 | D8: 출근·등교 전 묵상 시간
A9: 신약 1번째 업로드 시간 | C9: 12:30 | D9: 점심 시간
A10: 구약 2번째 업로드 시간 | C10: 18:30 | D10: 퇴근 시간
A11: 신약 2번째 업로드 시간 | C11: 21:30 | D11: 잠들기 전. 프로젝트1(애니메이션)은 17:00 전후로 두어 겹치지 않게
A12: 낭독 속도 (글자/초) | C12: 5 | D12: 차분한 낭독 기준. 권장 영상 길이 계산에 사용
A14: 전체 규모 (자동 계산)
A15: 전체 편수 | C15: =COUNTA(구절목록!$B$2:$B$729) -> 728 | D15: 편
A16: 구약 / 신약 | C16: =COUNTIF(구절목록!$C$2:$C$729,"구약")&" / "&COUNTIF(구절목록!$C$2:$C$729,"신약") -> 364 / 364 | D16: 편
A17: 포함된 책 | C17: =COUNTIF(권별점검!$C$2:$C$67,">0") -> 66 | D17: 권 / 66권
A18: 마지막 업로드일 | C18: =MAX(구절목록!$R$2:$R$729) -> 46569
A19: 전체 기간 | C19: =MAX(구절목록!$R$2:$R$729)-안내!$C$6+1 -> 182 | D19: 일 (목표 182일 이내)
A20: 본문 입력 완료 | C20: =COUNTIF(구절목록!$L$2:$L$729,"대조 완료")&" / "&COUNTA(구절목록!$B$2:$B$729) -> 0 / 728 | D20: 편
A22: 운영 원칙
A23: 말씀에만 집중 | B23: 영상에는 해설·진행자·내레이션 없이 구절 낭독과 자막만. 설명이 꼭 필요한 구절은 '설명란 문구'를 유튜브 설명란·인스타 게시글에만 적음
A24: 트랙 | B24: 구약 트랙과 신약 트랙이 각각 성경 순서대로 동시에 진행 (창세기→말라기, 마태복음→요한계시록)
A25: 채널 | B25: 프로젝트1과 같은 채널. '말씀' 재생목록으로 구분하고 업로드 시간을 겹치지 않게
A26: 성경 본문 | B26: 개역한글판만 사용. 본문은 공개된 원문에서 붙여 넣고 장절별로 대조 (기억이나 다른 번역에서 옮기지 않음)
A27: 선정 기준 | B27: 66권 모두 1구절 이상. 책의 분량과 많이 암송·인용되는 구절을 함께 고려. 한 절만 떼어 쓰면 뜻이 달라지는 구절은 피하거나 설명란 문구를 붙임

Sheet 구절목록
A1: 순번 | B1: 코드 | C1: 트랙 | D1: 트랙 회차 | E1: 회차 표기 | F1: 책 | G1: 장절 | H1: 자막 출처 표기 | I1: 주제 | J1: 화면 배경 | K1: 본문 (개역한글) | L1: 본문 상태 | M1: 글자 수 | N1: 권장 길이(초) | O1: 제목안 | P1: 해시태그 | Q1: 설명란 문구 | R1: 업로드일 | S1: 업로드 시간 | T1: 요일 | U1: 영상 | V1: 업로드 | W1: 조회수 | X1: 시청 vs 넘김(%) | Y1: 비고
A2: 1 | B2: W0001 | C2: 구약 | D2: 1 | E2: =C2&"말씀 #"&TEXT(D2,"000") -> 구약말씀 #001 | F2: 창세기 | G2: 1:1 | H2: (창 1:1, 개역한글) | I2: 창조 | J2: 하늘·별 | L2: 미입력 | M2: =LEN(K2) -> 0 | N2: =IF(M2=0,"-",ROUND(3+M2/안내!$C$12,0)) -> - | O2: =IF(K2="","(본문 입력 후 자동) | 창 1:1",IF(LEN(K2)>28,LEFT(K2,28)&"…",K2)&" | 창 1:1") -> (본문 입력 후 자동) | 창 1:1 | P2: ="#"&SUBSTITUTE(안내!$C$5," ","")&" #성경구절 #말씀 #창세기 #창조" -> #오늘의말씀 #성경구절 #말씀 #창세기 #창조 | Q2: 성경 본문: 개역한글판 | R2: =안내!$C$6+INT((D2-1)/안내!$C$7) -> 46388 | S2: =IF(MOD(D2-1,안내!$C$7)=0,안내!$C$8,안내!$C$10) -> 06:30 | T2: =CHOOSE(WEEKDAY(R2,2),"월","화","수","목","금","토","일") -> 금 | U2: 미착수 | V2: 미착수
A3: 2 | B3: W0002 | C3: 구약 | D3: 2 | E3: =C3&"말씀 #"&TEXT(D3,"000") -> 구약말씀 #002 | F3: 창세기 | G3: 1:27 | H3: (창 1:27, 개역한글) | I3: 창조 | J3: 하늘·별 | L3: 미입력 | M3: =LEN(K3) -> 0 | N3: =IF(M3=0,"-",ROUND(3+M3/안내!$C$12,0)) -> - | O3: =IF(K3="","(본문 입력 후 자동) | 창 1:27",IF(LEN(K3)>28,LEFT(K3,28)&"…",K3)&" | 창 1:27") -> (본문 입력 후 자동) | 창 1:27 | P3: ="#"&SUBSTITUTE(안내!$C$5," ","")&" #성경구절 #말씀 #창세기 #창조" -> #오늘의말씀 #성경구절 #말씀 #창세기 #창조 | Q3: 성경 본문: 개역한글판 | R3: =안내!$C$6+INT((D3-1)/안내!$C$7) -> 46388 | S3: =IF(MOD(D3-1,안내!$C$7)=0,안내!$C$8,안내!$C$10) -> 18:30 | T3: =CHOOSE(WEEKDAY(R3,2),"월","화","수","목","금","토","일") -> 금 | U3: 미착수 | V3: 미착수
A4: 3 | B4: W0003 | C4: 구약 | D4: 3 | E4: =C4&"말씀 #"&TEXT(D4,"000") -> 구약말씀 #003 | F4: 창세기 | G4: 1:31 | H4: (창 1:31, 개역한글) | I4: 창조 | J4: 하늘·별 | L4: 미입력 | M4: =LEN(K4) -> 0 | N4: =IF(M4=0,"-",ROUND(3+M4/안내!$C$12,0)) -> - | O4: =IF(K4="","(본문 입력 후 자동) | 창 1:31",IF(LEN(K4)>28,LEFT(K4,28)&"…",K4)&" | 창 1:31") -> (본문 입력 후 자동) | 창 1:31 | P4: ="#"&SUBSTITUTE(안내!$C$5," ","")&" #성경구절 #말씀 #창세기 #창조" -> #오늘의말씀 #성경구절 #말씀 #창세기 #창조 | Q4: 성경 본문: 개역한글판 | R4: =안내!$C$6+INT((D4-1)/안내!$C$7) -> 46389 | S4: =IF(MOD(D4-1,안내!$C$7)=0,안내!$C$8,안내!$C$10) -> 06:30 | T4: =CHOOSE(WEEKDAY(R4,2),"월","화","수","목","금","토","일") -> 토 | U4: 미착수 | V4: 미착수
A5: 4 | B5: W0004 | C5: 구약 | D5: 4 | E5: =C5&"말씀 #"&TEXT(D5,"000") -> 구약말씀 #004 | F5: 창세기 | G5: 2:7 | H5: (창 2:7, 개역한글) | I5: 생명 | J5: 새벽빛 | L5: 미입력 | M5: =LEN(K5) -> 0 | N5: =IF(M5=0,"-",ROUND(3+M5/안내!$C$12,0)) -> - | O5: =IF(K5="","(본문 입력 후 자동) | 창 2:7",IF(LEN(K5)>28,LEFT(K5,28)&"…",K5)&" | 창 2:7") -> (본문 입력 후 자동) | 창 2:7 | P5: ="#"&SUBSTITUTE(안내!$C$5," ","")&" #성경구절 #말씀 #창세기 #생명" -> #오늘의말씀 #성경구절 #말씀 #창세기 #생명 | Q5: 성경 본문: 개역한글판 | R5: =안내!$C$6+INT((D5-1)/안내!$C$7) -> 46389 | S5: =IF(MOD(D5-1,안내!$C$7)=0,안내!$C$8,안내!$C$10) -> 18:30 | T5: =CHOOSE(WEEKDAY(R5,2),"월","화","수","목","금","토","일") -> 토 | U5: 미착수 | V5: 미착수
A6: 5 | B6: W0005 | C6: 구약 | D6: 5 | E6: =C6&"말씀 #"&TEXT(D6,"000") -> 구약말씀 #005 | F6: 창세기 | G6: 2:18 | H6: (창 2:18, 개역한글) | I6: 가정 | J6: 창가·식탁 | L6: 미입력 | M6: =LEN(K6) -> 0 | N6: =IF(M6=0,"-",ROUND(3+M6/안내!$C$12,0)) -> - | O6: =IF(K6="","(본문 입력 후 자동) | 창 2:18",IF(LEN(K6)>28,LEFT(K6,28)&"…",K6)&" | 창 2:18") -> (본문 입력 후 자동) | 창 2:18 | P6: ="#"&SUBSTITUTE(안내!$C$5," ","")&" #성경구절 #말씀 #창세기 #가정" -> #오늘의말씀 #성경구절 #말씀 #창세기 #가정 | Q6: 성경 본문: 개역한글판 | R6: =안내!$C$6+INT((D6-1)/안내!$C$7) -> 46390 | S6: =IF(MOD(D6-1,안내!$C$7)=0,안내!$C$8,안내!$C$10) -> 06:30 | T6: =CHOOSE(WEEKDAY(R6,2),"월","화","수","목","금","토","일") -> 일 | U6: 미착수 | V6: 미착수
A7: 6 | B7: W0006 | C7: 구약 | D7: 6 | E7: =C7&"말씀 #"&TEXT(D7,"000") -> 구약말씀 #006 | F7: 창세기 | G7: 3:9 | H7: (창 3:9, 개역한글) | I7: 은혜 | J7: 잔잔한 물 | L7: 미입력 | M7: =LEN(K7) -> 0 | N7: =IF(M7=0,"-",ROUND(3+M7/안내!$C$12,0)) -> - | O7: =IF(K7="","(본문 입력 후 자동) | 창 3:9",IF(LEN(K7)>28,LEFT(K7,28)&"…",K7)&" | 창 3:9") -> (본문 입력 후 자동) | 창 3:9 | P7: ="#"&SUBSTITUTE(안내!$C$5," ","")&" #성경구절 #말씀 #창세기 #은혜" -> #오늘의말씀 #성경구절 #말씀 #창세기 #은혜 | Q7: 성경 본문: 개역한글판 | R7: =안내!$C$6+INT((D7-1)/안내!$C$7) -> 46390 | S7: =IF(MOD(D7-1,안내!$C$7)=0,안내!$C$8,안내!$C$10) -> 18:30 | T7: =CHOOSE(WEEKDAY(R7,2),"월","화","수","목","금","토","일") -> 일 | U7: 미착수 | V7: 미착수
A8: 7 | B8: W0007 | C8: 구약 | D8: 7 | E8: =C8&"말씀 #"&TEXT(D8,"000") -> 구약말씀 #007 | F8: 창세기 | G8: 3:15 | H8: (창 3:15, 개역한글) | I8: 구원 | J8: 제단·십자가 | L8: 미입력 | M8: =LEN(K8) -> 0 | N8: =IF(M8=0,"-",ROUND(3+M8/안내!$C$12,0)) -> - | O8: =IF(K8="","(본문 입력 후 자동) | 창 3:15",IF(LEN(K8)>28,LEFT(K8,28)&"…",K8)&" | 창 3:15") -> (본문 입력 후 자동) | 창 3:15 | P8: ="#"&SUBSTITUTE(안내!$C$5," ","")&" #성경구절 #말씀 #창세기 #구원" -> #오늘의말씀 #성경구절 #말씀 #창세기 #구원 | Q8: 여자의 후손이 뱀의 머리를 상하게 하리라는 약속은 그리스도의 승리를 가리킵니다(원시복음). 성경 본문: 개역한글판 | R8: =안내!$C$6+INT((D8-1)/안내!$C$7) -> 46391 | S8: =IF(MOD(D8-1,안내!$C$7)=0,안내!$C$8,안내!$C$10) -> 06:30 | T8: =CHOOSE(WEEKDAY(R8,2),"월","화","수","목","금","토","일") -> 월 | U8: 미착수 | V8: 미착수
A9: 8 | B9: W0008 | C9: 구약 | D9: 8 | E9: =C9&"말씀 #"&TEXT(D9,"000") -> 구약말씀 #008 | F9: 창세기 | G9: 6:8 | H9: (창 6:8, 개역한글) | I9: 은혜 | J9: 잔잔한 물 | L9: 미입력 | M9: =LEN(K9) -> 0 | N9: =IF(M9=0,"-",ROUND(3+M9/안내!$C$12,0)) -> - | O9: =IF(K9="","(본문 입력 후 자동) | 창 6:8",IF(LEN(K9)>28,LEFT(K9,28)&"…",K9)&" | 창 6:8") -> (본문 입력 후 자동) | 창 6:8 | P9: ="#"&SUBSTITUTE(안내!$C$5," ","")&" #성경구절 #말씀 #창세기 #은혜" -> #오늘의말씀 #성경구절 #말씀 #창세기 #은혜 | Q9: 성경 본문: 개역한글판 | R9: =안내!$C$6+INT((D9-1)/안내!$C$7) -> 46391 | S9: =IF(MOD(D9-1,안내!$C$7)=0,안내!$C$8,안내!$C$10) -> 18:30 | T9: =CHOOSE(WEEKDAY(R9,2),"월","화","수","목","금","토","일") -> 월 | U9: 미착수 | V9: 미착수
A10: 9 | B10: W0009 | C10: 구약 | D10: 9 | E10: =C10&"말씀 #"&TEXT(D10,"000") -> 구약말씀 #009 | F10: 창세기 | G10: 8:22 | H10: (창 8:22, 개역한글) | I10: 신실하심 | J10: 바위산·광야 | L10: 미입력 | M10: =LEN(K10) -> 0 | N10: =IF(M10=0,"-",ROUND(3+M10/안내!$C$12,0)) -> - | O10: =IF(K10="","(본문 입력 후 자동) | 창 8:22",IF(LEN(K10)>28,LEFT(K10,28)&"…",K10)&" | 창 8:22") -> (본문 입력 후 자동) | 창 8:22 | P10: ="#"&SUBSTITUTE(안내!$C$5," ","")&" #성경구절 #말씀 #창세기 #신실하심" -> #오늘의말씀 #성경구절 #말씀 #창세기 #신실하심 | Q10: 성경 본문: 개역한글판 | R10: =안내!$C$6+INT((D10-1)/안내!$C$7) -> 46392 | S10: =IF(MOD(D10-1,안내!$C$7)=0,안내!$C$8,안내!$C$10) -> 06:30 | T10: =CHOOSE(WEEKDAY(R10,2),"월","화","수","목","금","토","일") -> 화 | U10: 미착수 | V10: 미착수
A11: 10 | B11: W0010 | C11: 구약 | D11: 10 | E11: =C11&"말씀 #"&TEXT(D11,"000") -> 구약말씀 #010 | F11: 창세기 | G11: 9:13 | H11: (창 9:13, 개역한글) | I11: 언약 | J11: 제단·십자가 | L11: 미입력 | M11: =LEN(K11) -> 0 | N11: =IF(M11=0,"-",ROUND(3+M11/안내!$C$12,0)) -> - | O11: =IF(K11="","(본문 입력 후 자동) | 창 9:13",IF(LEN(K11)>28,LEFT(K11,28)&"…",K11)&" | 창 9:13") -> (본문 입력 후 자동) | 창 9:13 | P11: ="#"&SUBSTITUTE(안내!$C$5," ","")&" #성경구절 #말씀 #창세기 #언약" -> #오늘의말씀 #성경구절 #말씀 #창세기 #언약 | Q11: 성경 본문: 개역한글판 | R11: =안내!$C$6+INT((D11-1)/안내!$C$7) -> 46392 | S11: =IF(MOD(D11-1,안내!$C$7)=0,안내!$C$8,안내!$C$10) -> 18:30 | T11: =CHOOSE(WEEKDAY(R11,2),"월","화","수","목","금","토","일") -> 화 | U11: 미착수 | V11: 미착수
A12: 11 | B12: W0011 | C12: 구약 | D12: 11 | E12: =C12&"말씀 #"&TEXT(D12,"000") -> 구약말씀 #011 | F12: 창세기 | G12: 12:1 | H12: (창 12:1, 개역한글) | I12: 순종 | J12: 길·등불 | L12: 미입력 | M12: =LEN(K12) -> 0 | N12: =IF(M12=0,"-",ROUND(3+M12/안내!$C$12,0)) -> - | O12: =IF(K12="","(본문 입력 후 자동) | 창 12:1",IF(LEN(K12)>28,LEFT(K12,28)&"…",K12)&" | 창 12:1") -> (본문 입력 후 자동) | 창 12:1 | P12: ="#"&SUBSTITUTE(안내!$C$5," ","")&" #성경구절 #말씀 #창세기 #순종" -> #오늘의말씀 #성경구절 #말씀 #창세기 #순종 | Q12: 성경 본문: 개역한글판 | R12: =안내!$C$6+INT((D12-1)/안내!$C$7) -> 46393 | S12: =IF(MOD(D12-1,안내!$C$7)=0,안내!$C$8,안내!$C$10) -> 06:30 | T12: =CHOOSE(WEEKDAY(R12,2),"월","화","수","목","금","토","일") -> 수 | U12: 미착수 | V12: 미착수
A13: 12 | B13: W0012 | C13: 구약 | D13: 12 | E13: =C13&"말씀 #"&TEXT(D13,"000") -> 구약말씀 #012 | F13: 창세기 | G13: 12:2 | H13: (창 12:2, 개역한글) | I13: 언약 | J13: 제단·십자가 | L13: 미입력 | M13: =LEN(K13) -> 0 | N13: =IF(M13=0,"-",ROUND(3+M13/안내!$C$12,0)) -> - | O13: =IF(K13="","(본문 입력 후 자동) | 창 12:2",IF(LEN(K13)>28,LEFT(K13,28)&"…",K13)&" | 창 12:2") -> (본문 입력 후 자동) | 창 12:2 | P13: ="#"&SUBSTITUTE(안내!$C$5," ","")&" #성경구절 #말씀 #창세기 #언약" -> #오늘의말씀 #성경구절 #말씀 #창세기 #언약 | Q13: 성경 본문: 개역한글판 | R13: =안내!$C$6+INT((D13-1)/안내!$C$7) -> 46393 | S13: =IF(MOD(D13-1,안내!$C$7)=0,안내!$C$8,안내!$C$10) -> 18:30 | T13: =CHOOSE(WEEKDAY(R13,2),"월","화","수","목","금","토","일") -> 수 | U13: 미착수 | V13: 미착수
A14: 13 | B14: W0013 | C14: 구약 | D14: 13 | E14: =C14&"말씀 #"&TEXT(D14,"000") -> 구약말씀 #013 | F14: 창세기 | G14: 15:1 | H14: (창 15:1, 개역한글) | I14: 위로 | J14: 잔잔한 물 | L14: 미입력 | M14: =LEN(K14) -> 0 | N14: =IF(M14=0,"-",ROUND(3+M14/안내!$C$12,0)) -> - | O14: =IF(K14="","(본문 입력 후 자동) | 창 15:1",IF(LEN(K14)>28,LEFT(K14,28)&"…",K14)&" | 창 15:1") -> (본문 입력 후 자동) | 창 15:1 | P14: ="#"&SUBSTITUTE(안내!$C$5," ","")&" #성경구절 #말씀 #창세기 #위로" -> #오늘의말씀 #성경구절 #말씀 #창세기 #위로 | Q14: 성경 본문: 개역한글판 | R14: =안내!$C$6+INT((D14-1)/안내!$C$7) -> 46394 | S14: =IF(MOD(D14-1,안내!$C$7)=0,안내!$C$8,안내!$C$10) -> 06:30 | T14: =CHOOSE(WEEKDAY(R14,2),"월","화","수","목","금","토","일") -> 목 | U14: 미착수 | V14: 미착수
A15: 14 | B15: W0014 | C15: 구약 | D15: 14 | E15: =C15&"말씀 #"&TEXT(D15,"000") -> 구약말씀 #014 | F15: 창세기 | G15: 15:6 | H15: (창 15:6, 개역한글) | I15: 믿음 | J15: 바위산·광야 | L15: 미입력 | M15: =LEN(K15) -> 0 | N15: =IF(M15=0,"-",ROUND(3+M15/안내!$C$12,0)) -> - | O15: =IF(K15="","(본문 입력 후 자동) | 창 15:6",IF(LEN(K15)>28,LEFT(K15,28)&"…",K15)&" | 창 15:6") -> (본문 입력 후 자동) | 창 15:6 | P15: ="#"&SUBSTITUTE(안내!$C$5," ","")&" #성경구절 #말씀 #창세기 #믿음" -> #오늘의말씀 #성경구절 #말씀 #창세기 #믿음 | Q15: 성경 본문: 개역한글판 | R15: =안내!$C$6+INT((D15-1)/안내!$C$7) -> 46394 | S15: =IF(MOD(D15-1,안내!$C$7)=0,안내!$C$8,안내!$C$10) -> 18:30 | T15: =CHOOSE(WEEKDAY(R15,2),"월","화","수","목","금","토","일") -> 목 | U15: 미착수 | V15: 미착수
A16: 15 | B16: W0015 | C16: 구약 | D16: 15 | E16: =C16&"말씀 #"&TEXT(D16,"000") -> 구약말씀 #015 | F16: 창세기 | G16: 16:13 | H16: (창 16:13, 개역한글) | I16: 위로 | J16: 잔잔한 물 | L16: 미입력 | M16: =LEN(K16) -> 0 | N16: =IF(M16=0,"-",ROUND(3+M16/안내!$C$12,0)) -> - | O16: =IF(K16="","(본문 입력 후 자동) | 창 16:13",IF(LEN(K16)>28,LEFT(K16,28)&"…",K16)&" | 창 16:13") -> (본문 입력 후 자동) | 창 16:13 | P16: ="#"&SUBSTITUTE(안내!$C$5," ","")&" #성경구절 #말씀 #창세기 #위로" -> #오늘의말씀 #성경구절 #말씀 #창세기 #위로 | Q16: 성경 본문: 개역한글판 | R16: =안내!$C$6+INT((D16-1)/안내!$C$7) -> 46395 | S16: =IF(MOD(D16-1,안내!$C$7)=0,안내!$C$8,안내!$C$10) -> 06:30 | T16: =CHOOSE(WEEKDAY(R16,2),"월","화","수","목","금","토","일") -> 금 | U16: 미착수 | V16: 미착수
A17: 16 | B17: W0016 | C17: 구약 | D17: 16 | E17: =C17&"말씀 #"&TEXT(D17,"000") -> 구약말씀 #016 | F17: 창세기 | G17: 18:14 | H17: (창 18:14, 개역한글) | I17: 능력 | J17: 바위산·광야 | L17: 미입력 | M17: =LEN(K17) -> 0 | N17: =IF(M17=0,"-",ROUND(3+M17/안내!$C$12,0)) -> - | O17: =IF(K17="","(본문 입력 후 자동) | 창 18:14",IF(LEN(K17)>28,LEFT(K17,28)&"…",K17)&" | 창 18:14") -> (본문 입력 후 자동) | 창 18:14 | P17: ="#"&SUBSTITUTE(안내!$C$5," ","")&" #성경구절 #말씀 #창세기 #능력" -> #오늘의말씀 #성경구절 #말씀 #창세기 #능력 | Q17: 성경 본문: 개역한글판 | R17: =안내!$C$6+INT((D17-1)/안내!$C$7) -> 46395 | S17: =IF(MOD(D17-1,안내!$C$7)=0,안내!$C$8,안내!$C$10) -> 18:30 | T17: =CHOOSE(WEEKDAY(R17,2),"월","화","수","목","금","토","일") -> 금 | U17: 미착수 | V17: 미착수
A18: 17 | B18: W0017 | C18: 구약 | D18: 17 | E18: =C18&"말씀 #"&TEXT(D18,"000") -> 구약말씀 #017 | F18: 창세기 | G18: 22:8 | H18: (창 22:8, 개역한글) | I18: 믿음 | J18: 바위산·광야 | L18: 미입력 | M18: =LEN(K18) -> 0 | N18: =IF(M18=0,"-",ROUND(3+M18/안내!$C$12,0)) -> - | O18: =IF(K18="","(본문 입력 후 자동) | 창 22:8",IF(LEN(K18)>28,LEFT(K18,28)&"…",K18)&" | 창 22:8") -> (본문 입력 후 자동) | 창 22:8 | P18: ="#"&SUBSTITUTE(안내!$C$5," ","")&" #성경구절 #말씀 #창세기 #믿음" -> #오늘의말씀 #성경구절 #말씀 #창세기 #믿음 | Q18: 성경 본문: 개역한글판 | R18: =안내!$C$6+INT((D18-1)/안내!$C$7) -> 46396 | S18: =IF(MOD(D18-1,안내!$C$7)=0,안내!$C$8,안내!$C$10) -> 06:30 | T18: =CHOOSE(WEEKDAY(R18,2),"월","화","수","목","금","토","일") -> 토 | U18: 미착수 | V18: 미착수
A19: 18 | B19: W0018 | C19: 구약 | D19: 18 | E19: =C19&"말씀 #"&TEXT(D19,"000") -> 구약말씀 #018 | F19: 창세기 | G19: 22:14 | H19: (창 22:14, 개역한글) | I19: 공급하심 | J19: 들판·나무 | L19: 미입력 | M19: =LEN(K19) -> 0 | N19: =IF(M19=0,"-",ROUND(3+M19/안내!$C$12,0)) -> - | O19: =IF(K19="","(본문 입력 후 자동) | 창 22:14",IF(LEN(K19)>28,LEFT(K19,28)&"…",K19)&" | 창 22:14") -> (본문 입력 후 자동) | 창 22:14 | P19: ="#"&SUBSTITUTE(안내!$C$5," ","")&" #성경구절 #말씀 #창세기 #공급하심" -> #오늘의말씀 #성경구절 #말씀 #창세기 #공급하심 | Q19: 성경 본문: 개역한글판 | R19: =안내!$C$6+INT((D19-1)/안내!$C$7) -> 46396 | S19: =IF(MOD(D19-1,안내!$C$7)=0,안내!$C$8,안내!$C$10) -> 18:30 | T19: =CHOOSE(WEEKDAY(R19,2),"월","화","수","목","금","토","일") -> 토 | U19: 미착수 | V19: 미착수
A20: 19 | B20: W0019 | C20: 구약 | D20: 19 | E20: =C20&"말씀 #"&TEXT(D20,"000") -> 구약말씀 #019 | F20: 창세기 | G20: 28:15 | H20: (창 28:15, 개역한글) | I20: 동행 | J20: 길·등불 | L20: 미입력 | M20: =LEN(K20) -> 0 | N20: =IF(M20=0,"-",ROUND(3+M20/안내!$C$12,0)) -> - | O20: =IF(K20="","(본문 입력 후 자동) | 창 28:15",IF(LEN(K20)>28,LEFT(K20,28)&"…",K20)&" | 창 28:15") -> (본문 입력 후 자동) | 창 28:15 | P20: ="#"&SUBSTITUTE(안내!$C$5," ","")&" #성경구절 #말씀 #창세기 #동행" -> #오늘의말씀 #성경구절 #말씀 #창세기 #동행 | Q20: 성경 본문: 개역한글판 | R20: =안내!$C$6+INT((D20-1)/안내!$C$7) -> 46397 | S20: =IF(MOD(D20-1,안내!$C$7)=0,안내!$C$8,안내!$C$10) -> 06:30 | T20: =CHOOSE(WEEKDAY(R20,2),"월","화","수","목","금","토","일") -> 일 | U20: 미착수 | V20: 미착수
A21: 20 | B21: W0020 | C21: 구약 | D21: 20 | E21: =C21&"말씀 #"&TEXT(D21,"000") -> 구약말씀 #020 | F21: 창세기 | G21: 28:16 | H21: (창 28:16, 개역한글) | I21: 임재 | J21: 하늘·별 | L21: 미입력 | M21: =LEN(K21) -> 0 | N21: =IF(M21=0,"-",ROUND(3+M21/안내!$C$12,0)) -> - | O21: =IF(K21="","(본문 입력 후 자동) | 창 28:16",IF(LEN(K21)>28,LEFT(K21,28)&"…",K21)&" | 창 28:16") -> (본문 입력 후 자동) | 창 28:16 | P21: ="#"&SUBSTITUTE(안내!$C$5," ","")&" #성경구절 #말씀 #창세기 #임재" -> #오늘의말씀 #성경구절 #말씀 #창세기 #임재 | Q21: 성경 본문: 개역한글판 | R21: =안내!$C$6+INT((D21-1)/안내!$C$7) -> 46397 | S21: =IF(MOD(D21-1,안내!$C$7)=0,안내!$C$8,안내!$C$10) -> 18:30 | T21: =CHOOSE(WEEKDAY(R21,2),"월","화","수","목","금","토","일") -> 일 | U21: 미착수 | V21: 미착수
A22: 21 | B22: W0021 | C22: 구약 | D22: 21 | E22: =C22&"말씀 #"&TEXT(D22,"000") -> 구약말씀 #021 | F22: 창세기 | G22: 32:28 | H22: (창 32:28, 개역한글) | I22: 기도 | J22: 제단·십자가 | L22: 미입력 | M22: =LEN(K22) -> 0 | N22: =IF(M22=0,"-",ROUND(3+M22/안내!$C$12,0)) -> - | O22: =IF(K22="","(본문 입력 후 자동) | 창 32:28",IF(LEN(K22)>28,LEFT(K22,28)&"…",K22)&" | 창 32:28") -> (본문 입력 후 자동) | 창 32:28 | P22: ="#"&SUBSTITUTE(안내!$C$5," ","")&" #성경구절 #말씀 #창세기 #기도" -> #오늘의말씀 #성경구절 #말씀 #창세기 #기도 | Q22: 성경 본문: 개역한글판 | R22: =안내!$C$6+INT((D22-1)/안내!$C$7) -> 46398 | S22: =IF(MOD(D22-1,안내!$C$7)=0,안내!$C$8,안내!$C$10) -> 06:30 | T22: =CHOOSE(WEEKDAY(R22,2),"월","화","수","목","금","토","일") -> 월 | U22: 미착수 | V22: 미착수
A23: 22 | B23: W0022 | C23: 구약 | D23: 22 | E23: =C23&"말씀 #"&TEXT(D23,"000") -> 구약말씀 #022 | F23: 창세기 | G23: 39:2 | H23: (창 39:2, 개역한글) | I23: 동행 | J23: 길·등불 | L23: 미입력 | M23: =LEN(K23) -> 0 | N23: =IF(M23=0,"-",ROUND(3+M23/안내!$C$12,0)) -> - | O23: =IF(K23="","(본문 입력 후 자동) | 창 39:2",IF(LEN(K23)>28,LEFT(K23,28)&"…",K23)&" | 창 39:2") -> (본문 입력 후 자동) | 창 39:2 | P23: ="#"&SUBSTITUTE(안내!$C$5," ","")&" #성경구절 #말씀 #창세기 #동행" -> #오늘의말씀 #성경구절 #말씀 #창세기 #동행 | Q23: 성경 본문: 개역한글판 | R23: =안내!$C$6+INT((D23-1)/안내!$C$7) -> 46398 | S23: =IF(MOD(D23-1,안내!$C$7)=0,안내!$C$8,안내!$C$10) -> 18:30 | T23: =CHOOSE(WEEKDAY(R23,2),"월","화","수","목","금","토","일") -> 월 | U23: 미착수 | V23: 미착수
A24: 23 | B24: W0023 | C24: 구약 | D24: 23 | E24: =C24&"말씀 #"&TEXT(D24,"000") -> 구약말씀 #023 | F24: 창세기 | G24: 50:20 | H24: (창 50:20, 개역한글) | I24: 섭리 | J24: 하늘·별 | L24: 미입력 | M24: =LEN(K24) -> 0 | N24: =IF(M24=0,"-",ROUND(3+M24/안내!$C$12,0)) -> - | O24: =IF(K24="","(본문 입력 후 자동) | 창 50:20",IF(LEN(K24)>28,LEFT(K24,28)&"…",K24)&" | 창 50:20") -> (본문 입력 후 자동) | 창 50:20 | P24: ="#"&SUBSTITUTE(안내!$C$5," ","")&" #성경구절 #말씀 #창세기 #섭리" -> #오늘의말씀 #성경구절 #말씀 #창세기 #섭리 | Q24: 성경 본문: 개역한글판 | R24: =안내!$C$6+INT((D24-1)/안내!$C$7) -> 46399 | S24: =IF(MOD(D24-1,안내!$C$7)=0,안내!$C$8,안내!$C$10) -> 06:30 | T24: =CHOOSE(WEEKDAY(R24,2),"월","화","수","목","금","토","일") -> 화 | U24: 미착수 | V24: 미착수
A25: 24 | B25: W0024 | C25: 구약 | D25: 24 | E25: =C25&"말씀 #"&TEXT(D25,"000") -> 구약말씀 #024 | F25: 출애굽기 | G25: 3:5 | H25: (출 3:5, 개역한글) | I25: 거룩 | J25: 하늘·별 | L25: 미입력 | M25: =LEN(K25) -> 0 | N25: =IF(M25=0,"-",ROUND(3+M25/안내!$C$12,0)) -> - | O25: =IF(K25="","(본문 입력 후 자동) | 출 3:5",IF(LEN(K25)>28,LEFT(K25,28)&"…",K25)&" | 출 3:5") -> (본문 입력 후 자동) | 출 3:5 | P25: ="#"&SUBSTITUTE(안내!$C$5," ","")&" #성경구절 #말씀 #출애굽기 #거룩" -> #오늘의말씀 #성경구절 #말씀 #출애굽기 #거룩 | Q25: 성경 본문: 개역한글판 | R25: =안내!$C$6+INT((D25-1)/안내!$C$7) -> 46399 | S25: =IF(MOD(D25-1,안내!$C$7)=0,안내!$C$8,안내!$C$10) -> 18:30 | T25: =CHOOSE(WEEKDAY(R25,2),"월","화","수","목","금","토","일") -> 화 | U25: 미착수 | V25: 미착수
A26: 25 | B26: W0025 | C26: 구약 | D26: 25 | E26: =C26&"말씀 #"&TEXT(D26,"000") -> 구약말씀 #025 | F26: 출애굽기 | G26: 3:14 | H26: (출 3:14, 개역한글) | I26: 하나님 | J26: 하늘·별 | L26: 미입력 | M26: =LEN(K26) -> 0 | N26: =IF(M26=0,"-",ROUND(3+M26/안내!$C$12,0)) -> - | O26: =IF(K26="","(본문 입력 후 자동) | 출 3:14",IF(LEN(K26)>28,LEFT(K26,28)&"…",K26)&" | 출 3:14") -> (본문 입력 후 자동) | 출 3:14 | P26: ="#"&SUBSTITUTE(안내!$C$5," ","")&" #성경구절 #말씀 #출애굽기 #하나님" -> #오늘의말씀 #성경구절 #말씀 #출애굽기 #하나님 | Q26: 성경 본문: 개역한글판 | R26: =안내!$C$6+INT((D26-1)/안내!$C$7) -> 46400 | S26: =IF(MOD(D26-1,안내!$C$7)=0,안내!$C$8,안내!$C$10) -> 06:30 | T26: =CHOOSE(WEEKDAY(R26,2),"월","화","수","목","금","토","일") -> 수 | U26: 미착수 | V26: 미착수
A27: 26 | B27: W0026 | C27: 구약 | D27: 26 | E27: =C27&"말씀 #"&TEXT(D27,"000") -> 구약말씀 #026 | F27: 출애굽기 | G27: 4:12 | H27: (출 4:12, 개역한글) | I27: 인도 | J27: 길·등불 | L27: 미입력 | M27: =LEN(K27) -> 0 | N27: =IF(M27=0,"-",ROUND(3+M27/안내!$C$12,0)) -> - | O27: =IF(K27="","(본문 입력 후 자동) | 출 4:12",IF(LEN(K27)>28,LEFT(K27,28)&"…",K27)&" | 출 4:12") -> (본문 입력 후 자동) | 출 4:12 | P27: ="#"&SUBSTITUTE(안내!$C$5," ","")&" #성경구절 #말씀 #출애굽기 #인도" -> #오늘의말씀 #성경구절 #말씀 #출애굽기 #인도 | Q27: 성경 본문: 개역한글판 | R27: =안내!$C$6+INT((D27-1)/안내!$C$7) -> 46400 | S27: =IF(MOD(D27-1,안내!$C$7)=0,안내!$C$8,안내!$C$10) -> 18:30 | T27: =CHOOSE(WEEKDAY(R27,2),"월","화","수","목","금","토","일") -> 수 | U27: 미착수 | V27: 미착수
A28: 27 | B28: W0027 | C28: 구약 | D28: 27 | E28: =C28&"말씀 #"&TEXT(D28,"000") -> 구약말씀 #027 | F28: 출애굽기 | G28: 6:7 | H28: (출 6:7, 개역한글) | I28: 언약 | J28: 제단·십자가 | L28: 미입력 | M28: =LEN(K28) -> 0 | N28: =IF(M28=0,"-",ROUND(3+M28/안내!$C$12,0)) -> - | O28: =IF(K28="","(본문 입력 후 자동) | 출 6:7",IF(LEN(K28)>28,LEFT(K28,28)&"…",K28)&" | 출 6:7") -> (본문 입력 후 자동) | 출 6:7 | P28: ="#"&SUBSTITUTE(안내!$C$5," ","")&" #성경구절 #말씀 #출애굽기 #언약" -> #오늘의말씀 #성경구절 #말씀 #출애굽기 #언약 | Q28: 성경 본문: 개역한글판 | R28: =안내!$C$6+INT((D28-1)/안내!$C$7) -> 46401 | S28: =IF(MOD(D28-1,안내!$C$7)=0,안내!$C$8,안내!$C$10) -> 06:30 | T28: =CHOOSE(WEEKDAY(R28,2),"월","화","수","목","금","토","일") -> 목 | U28: 미착수 | V28: 미착수
A29: 28 | B29: W0028 | C29: 구약 | D29: 28 | E29: =C29&"말씀 #"&TEXT(D29,"000") -> 구약말씀 #028 | F29: 출애굽기 | G29: 12:13 | H29: (출 12:13, 개역한글) | I29: 구원 | J29: 제단·십자가 | L29: 미입력 | M29: =LEN(K29) -> 0 | N29: =IF(M29=0,"-",ROUND(3+M29/안내!$C$12,0)) -> - | O29: =IF(K29="","(본문 입력 후 자동) | 출 12:13",IF(LEN(K29)>28,LEFT(K29,28)&"…",K29)&" | 출 12:13") -> (본문 입력 후 자동) | 출 12:13 | P29: ="#"&SUBSTITUTE(안내!$C$5," ","")&" #성경구절 #말씀 #출애굽기 #구원" -> #오늘의말씀 #성경구절 #말씀 #출애굽기 #구원 | Q29: 성경 본문: 개역한글판 | R29: =안내!$C$6+INT((D29-1)/안내!$C$7) -> 46401 | S29: =IF(MOD(D29-1,안내!$C$7)=0,안내!$C$8,안내!$C$10) -> 18:30 | T29: =CHOOSE(WEEKDAY(R29,2),"월","화","수","목","금","토","일") -> 목 | U29: 미착수 | V29: 미착수
A30: 29 | B30: W0029 | C30: 구약 | D30: 29 | E30: =C30&"말씀 #"&TEXT(D30,"000") -> 구약말씀 #029 | F30: 출애굽기 | G30: 14:13 | H30: (출 14:13, 개역한글) | I30: 구원 | J30: 제단·십자가 | L30: 미입력 | M30: =LEN(K30) -> 0 | N30: =IF(M30=0,"-",ROUND(3+M30/안내!$C$12,0)) -> - | O30: =IF(K30="","(본문 입력 후 자동) | 출 14:13",IF(LEN(K30)>28,LEFT(K30,28)&"…",K30)&" | 출 14:13") -> (본문 입력 후 자동) | 출 14:13 | P30: ="#"&SUBSTITUTE(안내!$C$5," ","")&" #성경구절 #말씀 #출애굽기 #구원" -> #오늘의말씀 #성경구절 #말씀 #출애굽기 #구원 | Q30: 성경 본문: 개역한글판 | R30: =안내!$C$6+INT((D30-1)/안내!$C$7) -> 46402 | S30: =IF(MOD(D30-1,안내!$C$7)=0,안내!$C$8,안내!$C$10) -> 06:30 | T30: =CHOOSE(WEEKDAY(R30,2),"월","화","수","목","금","토","일") -> 금 | U30: 미착수 | V30: 미착수
A31: 30 | B31: W0030 | C31: 구약 | D31: 30 | E31: =C31&"말씀 #"&TEXT(D31,"000") -> 구약말씀 #030 | F31: 출애굽기 | G31: 14:14 | H31: (출 14:14, 개역한글) | I31: 능력 | J31: 바위산·광야 | L31: 미입력 | M31: =LEN(K31) -> 0 | N31: =IF(M31=0,"-",ROUND(3+M31/안내!$C$12,0)) -> - | O31: =IF(K31="","(본문 입력 후 자동) | 출 14:14",IF(LEN(K31)>28,LEFT(K31,28)&"…",K31)&" | 출 14:14") -> (본문 입력 후 자동) | 출 14:14 | P31: ="#"&SUBSTITUTE(안내!$C$5," ","")&" #성경구절 #말씀 #출애굽기 #능력" -> #오늘의말씀 #성경구절 #말씀 #출애굽기 #능력 | Q31: 성경 본문: 개역한글판 | R31: =안내!$C$6+INT((D31-1)/안내!$C$7) -> 46402 | S31: =IF(MOD(D31-1,안내!$C$7)=0,안내!$C$8,안내!$C$10) -> 18:30 | T31: =CHOOSE(WEEKDAY(R31,2),"월","화","수","목","금","토","일") -> 금 | U31: 미착수 | V31: 미착수
A32: 31 | B32: W0031 | C32: 구약 | D32: 31 | E32: =C32&"말씀 #"&TEXT(D32,"000") -> 구약말씀 #031 | F32: 출애굽기 | G32: 15:2 | H32: (출 15:2, 개역한글) | I32: 찬양 | J32: 하늘·별 | L32: 미입력 | M32: =LEN(K32) -> 0 | N32: =IF(M32=0,"-",ROUND(3+M32/안내!$C$12,0)) -> - | O32: =IF(K32="","(본문 입력 후 자동) | 출 15:2",IF(LEN(K32)>28,LEFT(K32,28)&"…",K32)&" | 출 15:2") -> (본문 입력 후 자동) | 출 15:2 | P32: ="#"&SUBSTITUTE(안내!$C$5," ","")&" #성경구절 #말씀 #출애굽기 #찬양" -> #오늘의말씀 #성경구절 #말씀 #출애굽기 #찬양 | Q32: 성경 본문: 개역한글판 | R32: =안내!$C$6+INT((D32-1)/안내!$C$7) -> 46403 | S32: =IF(MOD(D32-1,안내!$C$7)=0,안내!$C$8,안내!$C$10) -> 06:30 | T32: =CHOOSE(WEEKDAY(R32,2),"월","화","수","목","금","토","일") -> 토 | U32: 미착수 | V32: 미착수
A33: 32 | B33: W0032 | C33: 구약 | D33: 32 | E33: =C33&"말씀 #"&TEXT(D33,"000") -> 구약말씀 #032 | F33: 출애굽기 | G33: 15:26 | H33: (출 15:26, 개역한글) | I33: 치료 | J33: 잔잔한 물 | L33: 미입력 | M33: =LEN(K33) -> 0 | N33: =IF(M33=0,"-",ROUND(3+M33/안내!$C$12,0)) -> - | O33: =IF(K33="","(본문 입력 후 자동) | 출 15:26",IF(LEN(K33)>28,LEFT(K33,28)&"…",K33)&" | 출 15:26") -> (본문 입력 후 자동) | 출 15:26 | P33: ="#"&SUBSTITUTE(안내!$C$5," ","")&" #성경구절 #말씀 #출애굽기 #치료" -> #오늘의말씀 #성경구절 #말씀 #출애굽기 #치료 | Q33: 성경 본문: 개역한글판 | R33: =안내!$C$6+INT((D33-1)/안내!$C$7) -> 46403 | S33: =IF(MOD(D33-1,안내!$C$7)=0,안내!$C$8,안내!$C$10) -> 18:30 | T33: =CHOOSE(WEEKDAY(R33,2),"월","화","수","목","금","토","일") -> 토 | U33: 미착수 | V33: 미착수
A34: 33 | B34: W0033 | C34: 구약 | D34: 33 | E34: =C34&"말씀 #"&TEXT(D34,"000") -> 구약말씀 #033 | F34: 출애굽기 | G34: 16:4 | H34: (출 16:4, 개역한글) | I34: 공급하심 | J34: 들판·나무 | L34: 미입력 | M34: =LEN(K34) -> 0 | N34: =IF(M34=0,"-",ROUND(3+M34/안내!$C$12,0)) -> - | O34: =IF(K34="","(본문 입력 후 자동) | 출 16:4",IF(LEN(K34)>28,LEFT(K34,28)&"…",K34)&" | 출 16:4") -> (본문 입력 후 자동) | 출 16:4 | P34: ="#"&SUBSTITUTE(안내!$C$5," ","")&" #성경구절 #말씀 #출애굽기 #공급하심" -> #오늘의말씀 #성경구절 #말씀 #출애굽기 #공급하심 | Q34: 성경 본문: 개역한글판 | R34: =안내!$C$6+INT((D34-1)/안내!$C$7) -> 46404 | S34: =IF(MOD(D34-1,안내!$C$7)=0,안내!$C$8,안내!$C$10) -> 06:30 | T34: =CHOOSE(WEEKDAY(R34,2),"월","화","수","목","금","토","일") -> 일 | U34: 미착수 | V34: 미착수
A35: 34 | B35: W0034 | C35: 구약 | D35: 34 | E35: =C35&"말씀 #"&TEXT(D35,"000") -> 구약말씀 #034 | F35: 출애굽기 | G35: 17:15 | H35: (출 17:15, 개역한글) | I35: 승리 | J35: 바위산·광야 | L35: 미입력 | M35: =LEN(K35) -> 0 | N35: =IF(M35=0,"-",ROUND(3+M35/안내!$C$12,0)) -> - | O35: =IF(K35="","(본문 입력 후 자동) | 출 17:15",IF(LEN(K35)>28,LEFT(K35,28)&"…",K35)&" | 출 17:15") -> (본문 입력 후 자동) | 출 17:15 | P35: ="#"&SUBSTITUTE(안내!$C$5," ","")&" #성경구절 #말씀 #출애굽기 #승리" -> #오늘의말씀 #성경구절 #말씀 #출애굽기 #승리 | Q35: 성경 본문: 개역한글판 | R35: =안내!$C$6+INT((D35-1)/안내!$C$7) -> 46404 | S35: =IF(MOD(D35-1,안내!$C$7)=0,안내!$C$8,안내!$C$10) -> 18:30 | T35: =CHOOSE(WEEKDAY(R35,2),"월","화","수","목","금","토","일") -> 일 | U35: 미착수 | V35: 미착수
A36: 35 | B36: W0035 | C36: 구약 | D36: 35 | E36: =C36&"말씀 #"&TEXT(D36,"000") -> 구약말씀 #035 | F36: 출애굽기 | G36: 19:5 | H36: (출 19:5, 개역한글) | I36: 언약 | J36: 제단·십자가 | L36: 미입력 | M36: =LEN(K36) -> 0 | N36: =IF(M36=0,"-",ROUND(3+M36/안내!$C$12,0)) -> - | O36: =IF(K36="","(본문 입력 후 자동) | 출 19:5",IF(LEN(K36)>28,LEFT(K36,28)&"…",K36)&" | 출 19:5") -> (본문 입력 후 자동) | 출 19:5 | P36: ="#"&SUBSTITUTE(안내!$C$5," ","")&" #성경구절 #말씀 #출애굽기 #언약" -> #오늘의말씀 #성경구절 #말씀 #출애굽기 #언약 | Q36: 성경 본문: 개역한글판 | R36: =안내!$C$6+INT((D36-1)/안내!$C$7) -> 46405 | S36: =IF(MOD(D36-1,안내!$C$7)=0,안내!$C$8,안내!$C$10) -> 06:30 | T36: =CHOOSE(WEEKDAY(R36,2),"월","화","수","목","금","토","일") -> 월 | U36: 미착수 | V36: 미착수
A37: 36 | B37: W0036 | C37: 구약 | D37: 36 | E37: =C37&"말씀 #"&TEXT(D37,"000") -> 구약말씀 #036 | F37: 출애굽기 | G37: 20:3 | H37: (출 20:3, 개역한글) | I37: 계명 | J37: 제단·십자가 | L37: 미입력 | M37: =LEN(K37) -> 0 | N37: =IF(M37=0,"-",ROUND(3+M37/안내!$C$12,0)) -> - | O37: =IF(K37="","(본문 입력 후 자동) | 출 20:3",IF(LEN(K37)>28,LEFT(K37,28)&"…",K37)&" | 출 20:3") -> (본문 입력 후 자동) | 출 20:3 | P37: ="#"&SUBSTITUTE(안내!$C$5," ","")&" #성경구절 #말씀 #출애굽기 #계명" -> #오늘의말씀 #성경구절 #말씀 #출애굽기 #계명 | Q37: 성경 본문: 개역한글판 | R37: =안내!$C$6+INT((D37-1)/안내!$C$7) -> 46405 | S37: =IF(MOD(D37-1,안내!$C$7)=0,안내!$C$8,안내!$C$10) -> 18:30 | T37: =CHOOSE(WEEKDAY(R37,2),"월","화","수","목","금","토","일") -> 월 | U37: 미착수 | V37: 미착수
A38: 37 | B38: W0037 | C38: 구약 | D38: 37 | E38: =C38&"말씀 #"&TEXT(D38,"000") -> 구약말씀 #037 | F38: 출애굽기 | G38: 20:12 | H38: (출 20:12, 개역한글) | I38: 가정 | J38: 창가·식탁 | L38: 미입력 | M38: =LEN(K38) -> 0 | N38: =IF(M38=0,"-",ROUND(3+M38/안내!$C$12,0)) -> - | O38: =IF(K38="","(본문 입력 후 자동) | 출 20:12",IF(LEN(K38)>28,LEFT(K38,28)&"…",K38)&" | 출 20:12") -> (본문 입력 후 자동) | 출 20:12 | P38: ="#"&SUBSTITUTE(안내!$C$5," ","")&" #성경구절 #말씀 #출애굽기 #가정" -> #오늘의말씀 #성경구절 #말씀 #출애굽기 #가정 | Q38: 성경 본문: 개역한글판 | R38: =안내!$C$6+INT((D38-1)/안내!$C$7) -> 46406 | S38: =IF(MOD(D38-1,안내!$C$7)=0,안내!$C$8,안내!$C$10) -> 06:30 | T38: =CHOOSE(WEEKDAY(R38,2),"월","화","수","목","금","토","일") -> 화 | U38: 미착수 | V38: 미착수
A39: 38 | B39: W0038 | C39: 구약 | D39: 38 | E39: =C39&"말씀 #"&TEXT(D39,"000") -> 구약말씀 #038 | F39: 출애굽기 | G39: 33:14 | H39: (출 33:14, 개역한글) | I39: 평안 | J39: 잔잔한 물 | L39: 미입력 | M39: =LEN(K39) -> 0 | N39: =IF(M39=0,"-",ROUND(3+M39/안내!$C$12,0)) -> - | O39: =IF(K39="","(본문 입력 후 자동) | 출 33:14",IF(LEN(K39)>28,LEFT(K39,28)&"…",K39)&" | 출 33:14") -> (본문 입력 후 자동) | 출 33:14 | P39: ="#"&SUBSTITUTE(안내!$C$5," ","")&" #성경구절 #말씀 #출애굽기 #평안" -> #오늘의말씀 #성경구절 #말씀 #출애굽기 #평안 | Q39: 성경 본문: 개역한글판 | R39: =안내!$C$6+INT((D39-1)/안내!$C$7) -> 46406 | S39: =IF(MOD(D39-1,안내!$C$7)=0,안내!$C$8,안내!$C$10) -> 18:30 | T39: =CHOOSE(WEEKDAY(R39,2),"월","화","수","목","금","토","일") -> 화 | U39: 미착수 | V39: 미착수
A40: 39 | B40: W0039 | C40: 구약 | D40: 39 | E40: =C40&"말씀 #"&TEXT(D40,"000") -> 구약말씀 #039 | F40: 출애굽기 | G40: 34:6 | H40: (출 34:6, 개역한글) | I40: 은혜 | J40: 잔잔한 물 | L40: 미입력 | M40: =LEN(K40) -> 0 | N40: =IF(M40=0,"-",ROUND(3+M40/안내!$C$12,0)) -> - | O40: =IF(K40="","(본문 입력 후 자동) | 출 34:6",IF(LEN(K40)>28,LEFT(K40,28)&"…",K40)&" | 출 34:6") -> (본문 입력 후 자동) | 출 34:6 | P40: ="#"&SUBSTITUTE(안내!$C$5," ","")&" #성경구절 #말씀 #출애굽기 #은혜" -> #오늘의말씀 #성경구절 #말씀 #출애굽기 #은혜 | Q40: 성경 본문: 개역한글판 | R40: =안내!$C$6+INT((D40-1)/안내!$C$7) -> 46407 | S40: =IF(MOD(D40-1,안내!$C$7)=0,안내!$C$8,안내!$C$10) -> 06:30 | T40: =CHOOSE(WEEKDAY(R40,2),"월","화","수","목","금","토","일") -> 수 | U40: 미착수 | V40: 미착수
...

Sheet 권별점검
A1: 책 | B1: 구약/신약 | C1: 구절 수 | D1: 장 수 | E1: 첫 업로드일 | F1: 마지막 업로드일 | G1: 결과
A2: 창세기 | B2: 구약 | C2: =COUNTIF(구절목록!$F$2:$F$729,A2) -> 23 | D2: 50 | E2: =_xlfn.MINIFS(구절목록!$R$2:$R$729,구절목록!$F$2:$F$729,A2) -> 46388 | F2: =_xlfn.MAXIFS(구절목록!$R$2:$R$729,구절목록!$F$2:$F$729,A2) -> 46399 | G2: =IF(C2>0,"정상","구절 없음") -> 정상
A3: 출애굽기 | B3: 구약 | C3: =COUNTIF(구절목록!$F$2:$F$729,A3) -> 16 | D3: 40 | E3: =_xlfn.MINIFS(구절목록!$R$2:$R$729,구절목록!$F$2:$F$729,A3) -> 46399 | F3: =_xlfn.MAXIFS(구절목록!$R$2:$R$729,구절목록!$F$2:$F$729,A3) -> 46407 | G3: =IF(C3>0,"정상","구절 없음") -> 정상
A4: 레위기 | B4: 구약 | C4: =COUNTIF(구절목록!$F$2:$F$729,A4) -> 6 | D4: 27 | E4: =_xlfn.MINIFS(구절목록!$R$2:$R$729,구절목록!$F$2:$F$729,A4) -> 46407 | F4: =_xlfn.MAXIFS(구절목록!$R$2:$R$729,구절목록!$F$2:$F$729,A4) -> 46410 | G4: =IF(C4>0,"정상","구절 없음") -> 정상
A5: 민수기 | B5: 구약 | C5: =COUNTIF(구절목록!$F$2:$F$729,A5) -> 7 | D5: 36 | E5: =_xlfn.MINIFS(구절목록!$R$2:$R$729,구절목록!$F$2:$F$729,A5) -> 46410 | F5: =_xlfn.MAXIFS(구절목록!$R$2:$R$729,구절목록!$F$2:$F$729,A5) -> 46413 | G5: =IF(C5>0,"정상","구절 없음") -> 정상
A6: 신명기 | B6: 구약 | C6: =COUNTIF(구절목록!$F$2:$F$729,A6) -> 14 | D6: 34 | E6: =_xlfn.MINIFS(구절목록!$R$2:$R$729,구절목록!$F$2:$F$729,A6) -> 46414 | F6: =_xlfn.MAXIFS(구절목록!$R$2:$R$729,구절목록!$F$2:$F$729,A6) -> 46420 | G6: =IF(C6>0,"정상","구절 없음") -> 정상
A7: 여호수아 | B7: 구약 | C7: =COUNTIF(구절목록!$F$2:$F$729,A7) -> 6 | D7: 24 | E7: =_xlfn.MINIFS(구절목록!$R$2:$R$729,구절목록!$F$2:$F$729,A7) -> 46421 | F7: =_xlfn.MAXIFS(구절목록!$R$2:$R$729,구절목록!$F$2:$F$729,A7) -> 46423 | G7: =IF(C7>0,"정상","구절 없음") -> 정상
A8: 사사기 | B8: 구약 | C8: =COUNTIF(구절목록!$F$2:$F$729,A8) -> 4 | D8: 21 | E8: =_xlfn.MINIFS(구절목록!$R$2:$R$729,구절목록!$F$2:$F$729,A8) -> 46424 | F8: =_xlfn.MAXIFS(구절목록!$R$2:$R$729,구절목록!$F$2:$F$729,A8) -> 46425 | G8: =IF(C8>0,"정상","구절 없음") -> 정상
A9: 룻기 | B9: 구약 | C9: =COUNTIF(구절목록!$F$2:$F$729,A9) -> 3 | D9: 4 | E9: =_xlfn.MINIFS(구절목록!$R$2:$R$729,구절목록!$F$2:$F$729,A9) -> 46426 | F9: =_xlfn.MAXIFS(구절목록!$R$2:$R$729,구절목록!$F$2:$F$729,A9) -> 46427 | G9: =IF(C9>0,"정상","구절 없음") -> 정상
A10: 사무엘상 | B10: 구약 | C10: =COUNTIF(구절목록!$F$2:$F$729,A10) -> 8 | D10: 31 | E10: =_xlfn.MINIFS(구절목록!$R$2:$R$729,구절목록!$F$2:$F$729,A10) -> 46427 | F10: =_xlfn.MAXIFS(구절목록!$R$2:$R$729,구절목록!$F$2:$F$729,A10) -> 46431 | G10: =IF(C10>0,"정상","구절 없음") -> 정상
A11: 사무엘하 | B11: 구약 | C11: =COUNTIF(구절목록!$F$2:$F$729,A11) -> 5 | D11: 24 | E11: =_xlfn.MINIFS(구절목록!$R$2:$R$729,구절목록!$F$2:$F$729,A11) -> 46431 | F11: =_xlfn.MAXIFS(구절목록!$R$2:$R$729,구절목록!$F$2:$F$729,A11) -> 46433 | G11: =IF(C11>0,"정상","구절 없음") -> 정상
A12: 열왕기상 | B12: 구약 | C12: =COUNTIF(구절목록!$F$2:$F$729,A12) -> 6 | D12: 22 | E12: =_xlfn.MINIFS(구절목록!$R$2:$R$729,구절목록!$F$2:$F$729,A12) -> 46434 | F12: =_xlfn.MAXIFS(구절목록!$R$2:$R$729,구절목록!$F$2:$F$729,A12) -> 46436 | G12: =IF(C12>0,"정상","구절 없음") -> 정상
A13: 열왕기하 | B13: 구약 | C13: =COUNTIF(구절목록!$F$2:$F$729,A13) -> 4 | D13: 25 | E13: =_xlfn.MINIFS(구절목록!$R$2:$R$729,구절목록!$F$2:$F$729,A13) -> 46437 | F13: =_xlfn.MAXIFS(구절목록!$R$2:$R$729,구절목록!$F$2:$F$729,A13) -> 46438 | G13: =IF(C13>0,"정상","구절 없음") -> 정상
... A67: 요한계시록 | B67: 신약 | C67: =COUNTIF(구절목록!$F$2:$F$729,A67) -> 17 | D67: 22 | E67: =_xlfn.MINIFS(구절목록!$R$2:$R$729,구절목록!$F$2:$F$729,A67) -> 46561 | F67: =_xlfn.MAXIFS(구절목록!$R$2:$R$729,구절목록!$F$2:$F$729,A67) -> 46569 | G67: =IF(C67>0,"정상","구절 없음") -> 정상

Sheet 누락점검
A1: 누락 점검
A2: 결과가 모두 '정상'이어야 합니다.
A4: 점검 항목
A5: 항목 | B5: 현재 값 | C5: 기대 값 | D5: 결과
A6: 전체 편수 | B6: =COUNTA(구절목록!$B$2:$B$729) -> 728 | C6: 728 | D6: =IF(B6=C6,"정상","확인 필요") -> 정상
A7: 구약 편수 | B7: =COUNTIF(구절목록!$C$2:$C$729,"구약") -> 364 | C7: 364 | D7: =IF(B7=C7,"정상","확인 필요") -> 정상
A8: 신약 편수 | B8: =COUNTIF(구절목록!$C$2:$C$729,"신약") -> 364 | C8: 364 | D8: =IF(B8=C8,"정상","확인 필요") -> 정상
A9: 구절이 없는 책 | B9: =COUNTIF(권별점검!$C$2:$C$67,0) -> 0 | C9: 0 | D9: =IF(B9=C9,"정상","확인 필요") -> 정상
A10: 포함된 책 수 | B10: =COUNTIF(권별점검!$C$2:$C$67,">0") -> 66 | C10: 66 | D10: =IF(B10=C10,"정상","확인 필요") -> 정상
A11: 중복 구절 | B11: =SUMPRODUCT((COUNTIF(구절목록!$H$2:$H$729,구절목록!$H$2:$H$729)>1)*1) -> 0 | C11: 0 | D11: =IF(B11=C11,"정상","확인 필요") -> 정상
A12: 같은 날·같은 시간 겹친 업로드 | B12: =SUMPRODUCT((COUNTIFS(구절목록!$R$2:$R$729,구절목록!$R$2:$R$729,구절목록!$S$2:$S$729,구절목록!$S$2:$S$729)>1)*1) -> 0 | C12: 0 | D12: =IF(B12=C12,"정상","확인 필요") -> 정상
A13: 6개월(182일) 안에 끝나는가 (1 = 예) | B13: =IF(MAX(구절목록!$R$2:$R$729)-안내!$C$6+1<=182,1,0) -> 1 | C13: 1 | D13: =IF(B13=C13,"정상","확인 필요") -> 정상
A14: 트랙 회차 중복 | B14: =SUMPRODUCT((COUNTIFS(구절목록!$C$2:$C$729,구절목록!$C$2:$C$729,구절목록!$D$2:$D$729,구절목록!$D$2:$D$729)>1)*1) -> 0 | C14: 0 | D14: =IF(B14=C14,"정상","확인 필요") -> 정상
A15: 화면 배경이 정해지지 않은 구절 | B15: =COUNTBLANK(구절목록!$J$2:$J$729) -> 0 | C15: 0 | D15: =IF(B15=C15,"정상","확인 필요") -> 정상
A16: 전체 결과 | D16: =IF(COUNTIF(D6:D15,"정상")=10,"모두 정상","확인 필요 있음") -> 모두 정상
A18: 참고: 본문 입력 진행
A19: 본문이 아직 입력되지 않은 구절 | B19: =COUNTBLANK(구절목록!$K$2:$K$729) -> 728
A20: 본문 대조 완료 | B20: =COUNTIF(구절목록!$L$2:$L$729,"대조 완료") -> 0

Sheet 제작템플릿
A1: 말씀 숏폼 제작 템플릿
A2: 말씀에만 집중: 해설·진행자 없이 구절과 낭독만
A4: 1. 영상 구성 (15~25초)
A5: 구간 | B5: 내용 | C5: 연결 칸 | D5: 비고
A6: 0~1초 | B6: 배경 화면이 열리며 시그니처 사운드(프로젝트1과 다른 짧은 소리) | C6: 화면 배경 | D6: 첫 프레임부터 구절 첫 줄이 보이게 해 넘김을 줄임
A7: 1초~끝 3초 전 | B7: 구절을 한 줄씩 자막으로 띄우며 차분히 낭독. 해설·배경 설명 없음 | C7: 본문 (개역한글) | D7: 권장 길이(초) 칸 참고
A8: 마지막 3초 | B8: 구절 전체 자막 + 출처 '(창 1:1, 개역한글)' | C8: 자막 출처 표기 | D8: 멈춰서 다시 읽을 시간
A9: 반복 재생 | B9: 마지막 화면에서 첫 화면으로 자연스럽게 이어지게 | C9: - | D9: 반복 시청 유도
A11: 2. 화면 배경 기준 (사람 얼굴·하나님 형상 없이 풍경과 빛)
A12: 배경 분류 | B12: 장면 | C12: 해당 주제 | D12: 구절 수
A13: 새벽빛 | B13: 해 뜨는 지평선, 구름 사이로 퍼지는 새벽빛 | C13: 빛, 소망, 부활, 새 마음, 생명, 회복, 하나님 나라, 기쁨 | D13: =COUNTIF(구절목록!$J$2:$J$729,"새벽빛") -> 82
A14: 잔잔한 물 | B14: 잔잔한 호수, 맑은 시냇물, 물 위의 햇빛 | C14: 평안, 쉼, 위로, 치료, 은혜, 용서 | D14: =COUNTIF(구절목록!$J$2:$J$729,"잔잔한 물") -> 81
A15: 바위산·광야 | B15: 바위산, 광야 길, 견고한 바위와 넓은 하늘 | C15: 믿음, 신뢰, 담대함, 능력, 승리, 보호, 피난처, 연단, 신실하심 | D15: =COUNTIF(구절목록!$J$2:$J$729,"바위산·광야") -> 125
A16: 들판·나무 | B16: 밀밭, 올리브 나무, 열매 맺은 가지, 씨앗과 새싹 | C16: 말씀, 지혜, 성장, 나눔, 섬김, 공급하심, 복, 축복, 감사, 정의, 경건 | D16: =COUNTIF(구절목록!$J$2:$J$729,"들판·나무") -> 77
A17: 하늘·별 | B17: 별이 가득한 밤하늘, 구름 위 빛줄기, 은하수 | C17: 창조, 하나님, 섭리, 거룩, 찬양, 예배, 경외, 임재, 성령 | D17: =COUNTIF(구절목록!$J$2:$J$729,"하늘·별") -> 97
A18: 길·등불 | B18: 굽이진 오솔길, 밤길을 밝히는 등불, 먼 곳으로 이어진 길 | C18: 인도, 동행, 순종, 부르심, 헌신, 결단 | D18: =COUNTIF(구절목록!$J$2:$J$729,"길·등불") -> 59
A19: 창가·식탁 | B19: 따뜻한 햇살이 드는 창가, 빵과 잔이 놓인 나무 식탁 (사람 없이) | C19: 가정, 사랑, 연합, 교회, 마음, 말, 겸손 | D19: =COUNTIF(구절목록!$J$2:$J$729,"창가·식탁") -> 97
A20: 제단·십자가 | B20: 돌 제단, 언덕 위 십자가 실루엣과 빛, 열린 두루마리 | C20: 기도, 회개, 언약, 속죄, 구원, 복음, 자유, 계명 | D20: =COUNTIF(구절목록!$J$2:$J$729,"제단·십자가") -> 110
A22: 3. 자막·음성
A23: 항목 | B23: 기준 | C23: 비고
A24: 자막 | B24: 굵은 명조 또는 고딕, 한 줄 12~14자, 화면 가운데 | C24: 개역한글 원문 그대로. 띄어쓰기·맞춤법을 현대식으로 고치지 않음
A25: 낭독 | B25: 차분하고 또렷한 목소리 1명으로 고정 | C25: AI 음성은 상업 이용 허용 여부 확인
A26: 배경음악 | B26: 잔잔한 저작권 무료 음원. 낭독보다 충분히 작게 | C26: 찬송가·CCM 사용 금지
A27: 화면 비율 | B27: 1080×1920 (9:16) | C27: 상단·하단 플랫폼 UI 영역에는 자막을 두지 않음
A29: 4. 설명란·게시글
A30: 항목 | B30: 형식 | C30: 비고
A31: 유튜브 제목 | B31: 구절 앞부분… | 장절 | C31: '제목안' 칸 자동 생성
A32: 설명란 / 인스타 게시글 | B32: 구절 전문 + 장절 + (필요한 구절만) 설명란 문구 + '성경 본문: 개역한글판' | C32: '설명란 문구' 칸이 빨간 글씨인 구절은 문맥 설명을 꼭 넣기
A33: 해시태그 | B33: #시리즈명 #성경구절 #말씀 #책이름 #주제 | C33: '해시태그' 칸 자동 생성
A35: 5. 저작권·교리 원칙
A36: 원칙 | B36: 내용
A37: 본문 | B37: 개역한글판만 사용(저작재산권 보호기간 만료). 개역개정·새번역 등 다른 번역 문장을 섞지 않음
A38: 원문 확보 | B38: 공개된 개역한글 원문에서 장절별로 붙여 넣고 '본문 상태'를 '대조 완료'로 표시
A39: 문맥 | B39: 한 절만 떼어 쓰면 뜻이 달라질 수 있는 구절은 설명란 문구를 붙임 (예: 빌 4:13, 렘 29:11)
A40: 감수 | B40: 프로젝트1의 교리감수 기준(합동측)을 그대로 적용

Sheet 성과기록
A1: 성과 기록
A2: 구절목록의 노란 칸(조회수·시청 vs 넘김)에 입력하면 자동 집계됩니다.
A4: 주제 | B4: 구절 수 | C4: 입력된 편 | D4: 평균 조회수 | E4: 평균 시청 vs 넘김(%)
A5: 가정 | B5: =COUNTIF(구절목록!$I$2:$I$729,A5) -> 6 | C5: =COUNTIFS(구절목록!$I$2:$I$729,A5,구절목록!$W$2:$W$729,"<>") -> 0 | D5: =IFERROR(AVERAGEIFS(구절목록!$W$2:$W$729,구절목록!$I$2:$I$729,A5),"-") -> - | E5: =IFERROR(AVERAGEIFS(구절목록!$X$2:$X$729,구절목록!$I$2:$I$729,A5),"-") -> -
A6: 감사 | B6: =COUNTIF(구절목록!$I$2:$I$729,A6) -> 7 | C6: =COUNTIFS(구절목록!$I$2:$I$729,A6,구절목록!$W$2:$W$729,"<>") -> 0 | D6: =IFERROR(AVERAGEIFS(구절목록!$W$2:$W$729,구절목록!$I$2:$I$729,A6),"-") -> - | E6: =IFERROR(AVERAGEIFS(구절목록!$X$2:$X$729,구절목록!$I$2:$I$729,A6),"-") -> -
A7: 거룩 | B7: =COUNTIF(구절목록!$I$2:$I$729,A7) -> 9 | C7: =COUNTIFS(구절목록!$I$2:$I$729,A7,구절목록!$W$2:$W$729,"<>") -> 0 | D7: =IFERROR(AVERAGEIFS(구절목록!$W$2:$W$729,구절목록!$I$2:$I$729,A7),"-") -> - | E7: =IFERROR(AVERAGEIFS(구절목록!$X$2:$X$729,구절목록!$I$2:$I$729,A7),"-") -> -
A8: 결단 | B8: =COUNTIF(구절목록!$I$2:$I$729,A8) -> 1 | C8: =COUNTIFS(구절목록!$I$2:$I$729,A8,구절목록!$W$2:$W$729,"<>") -> 0 | D8: =IFERROR(AVERAGEIFS(구절목록!$W$2:$W$729,구절목록!$I$2:$I$729,A8),"-") -> - | E8: =IFERROR(AVERAGEIFS(구절목록!$X$2:$X$729,구절목록!$I$2:$I$729,A8),"-") -> -
A9: 겸손 | B9: =COUNTIF(구절목록!$I$2:$I$729,A9) -> 10 | C9: =COUNTIFS(구절목록!$I$2:$I$729,A9,구절목록!$W$2:$W$729,"<>") -> 0 | D9: =IFERROR(AVERAGEIFS(구절목록!$W$2:$W$729,구절목록!$I$2:$I$729,A9),"-") -> - | E9: =IFERROR(AVERAGEIFS(구절목록!$X$2:$X$729,구절목록!$I$2:$I$729,A9),"-") -> -
A10: 경건 | B10: =COUNTIF(구절목록!$I$2:$I$729,A10) -> 2 | C10: =COUNTIFS(구절목록!$I$2:$I$729,A10,구절목록!$W$2:$W$729,"<>") -> 0 | D10: =IFERROR(AVERAGEIFS(구절목록!$W$2:$W$729,구절목록!$I$2:$I$729,A10),"-") -> - | E10: =IFERROR(AVERAGEIFS(구절목록!$X$2:$X$729,구절목록!$I$2:$I$729,A10),"-") -> -
A11: 경외 | B11: =COUNTIF(구절목록!$I$2:$I$729,A11) -> 6 | C11: =COUNTIFS(구절목록!$I$2:$I$729,A11,구절목록!$W$2:$W$729,"<>") -> 0 | D11: =IFERROR(AVERAGEIFS(구절목록!$W$2:$W$729,구절목록!$I$2:$I$729,A11),"-") -> - | E11: =IFERROR(AVERAGEIFS(구절목록!$X$2:$X$729,구절목록!$I$2:$I$729,A11),"-") -> -
A12: 계명 | B12: =COUNTIF(구절목록!$I$2:$I$729,A12) -> 1 | C12: =COUNTIFS(구절목록!$I$2:$I$729,A12,구절목록!$W$2:$W$729,"<>") -> 0 | D12: =IFERROR(AVERAGEIFS(구절목록!$W$2:$W$729,구절목록!$I$2:$I$729,A12),"-") -> - | E12: =IFERROR(AVERAGEIFS(구절목록!$X$2:$X$729,구절목록!$I$2:$I$729,A12),"-") -> -
A13: 공급하심 | B13: =COUNTIF(구절목록!$I$2:$I$729,A13) -> 4 | C13: =COUNTIFS(구절목록!$I$2:$I$729,A13,구절목록!$W$2:$W$729,"<>") -> 0 | D13: =IFERROR(AVERAGEIFS(구절목록!$W$2:$W$729,구절목록!$I$2:$I$729,A13),"-") -> - | E13: =IFERROR(AVERAGEIFS(구절목록!$X$2:$X$729,구절목록!$I$2:$I$729,A13),"-") -> -
A14: 교회 | B14: =COUNTIF(구절목록!$I$2:$I$729,A14) -> 6 | C14: =COUNTIFS(구절목록!$I$2:$I$729,A14,구절목록!$W$2:$W$729,"<>") -> 0 | D14: =IFERROR(AVERAGEIFS(구절목록!$W$2:$W$729,구절목록!$I$2:$I$729,A14),"-") -> - | E14: =IFERROR(AVERAGEIFS(구절목록!$X$2:$X$729,구절목록!$I$2:$I$729,A14),"-") -> -
A15: 구원 | B15: =COUNTIF(구절목록!$I$2:$I$729,A15) -> 37 | C15: =COUNTIFS(구절목록!$I$2:$I$729,A15,구절목록!$W$2:$W$729,"<>") -> 0 | D15: =IFERROR(AVERAGEIFS(구절목록!$W$2:$W$729,구절목록!$I$2:$I$729,A15),"-") -> - | E15: =IFERROR(AVERAGEIFS(구절목록!$X$2:$X$729,구절목록!$I$2:$I$729,A15),"-") -> -
A16: 기도 | B16: =COUNTIF(구절목록!$I$2:$I$729,A16) -> 30 | C16: =COUNTIFS(구절목록!$I$2:$I$729,A16,구절목록!$W$2:$W$729,"<>") -> 0 | D16: =IFERROR(AVERAGEIFS(구절목록!$W$2:$W$729,구절목록!$I$2:$I$729,A16),"-") -> - | E16: =IFERROR(AVERAGEIFS(구절목록!$X$2:$X$729,구절목록!$I$2:$I$729,A16),"-") -> -
... A68: 회복 | B68: =COUNTIF(구절목록!$I$2:$I$729,A68) -> 2 | C68: =COUNTIFS(구절목록!$I$2:$I$729,A68,구절목록!$W$2:$W$729,"<>") -> 0 | D68: =IFERROR(AVERAGEIFS(구절목록!$W$2:$W$729,구절목록!$I$2:$I$729,A68),"-") -> - | E68: =IFERROR(AVERAGEIFS(구절목록!$X$2:$X$729,구절목록!$I$2:$I$729,A68),"-") -> -
